Workbook
Name FINNHUB_API_KEY: '7_Config'!$B$2

Sheet 0_Dashboard
A1: Market Dashboard（美股读盘框架）
A2: 把宏观流动性 × 微观基本面 × 价格行动落地为“可每周更新”的评分体系。
A5: 模块 | B5: 指标 | C5: 当前值(链接/输入) | D5: 环比 | E5: 阈值/规则 | F5: 状态(公式) | G5: 得分(公式) | H5: 注释
A6: 流动性 | B6: 宏观政策得分(合计) | C6: ='1_Macro_Liquidity'!H11 -> 0 | E6: >=2宽松; 0-1中性; <0收紧 | F6: =IF(C6="","",IF(C6>=2,"宽松",IF(C6>=0,"中性","收紧"))) -> 中性 | G6: =IF(C6="","",IF(C6>=2,1,IF(C6>=0,0,-1))) -> 0 | H6: 点阵图/中性利率/分歧/不确定性
A7: 流动性 | B7: 实际利率得分(最近) | C7: ='2_RealRate_Valuation'!B37 -> -1 | E7: 10Y TIPS <=0.75→+1 | F7: =IF(C7="","",IF(C7=1,"宽松",IF(C7=0,"中性","收紧"))) -> 收紧 | G7: =C7 -> -1 | H7: 实际利率下行利好成长
A8: 流动性 | B8: TGA得分(最近) | C8: =IFERROR(LOOKUP(2,1/('3_TGA_RRP'!F6:F35<>""),'3_TGA_RRP'!F6:F35),"") -> -1 | E8: TGA<8500→+1 | F8: =IF(C8="","",IF(C8=1,"释放",IF(C8=0,"中性","收缩"))) -> 收缩 | G8: =C8 -> -1 | H8: TGA下降=释放流动性
A9: 基本面 | B9: Mag7得分(加权) | C9: ='4_Micro_Fundamentals'!G25 -> 0.7145 | E9: >=0.3强; 0-0.29中; <0弱 | F9: =IF(C9="","",IF(C9>=0.3,"强",IF(C9>=0,"中","弱"))) -> 强 | G9: =IF(C9="","",IF(C9>=0.3,1,IF(C9>=0,0,-1))) -> 1 | H9: 超预期+利润率+FCF
A10: 情绪 | B10: 利好不涨比例 | C10: ='5_Price_Action'!B89 -> 0 | E10: <30%健康; 30-45%警惕; >45%风险 | F10: =IF(C10="","",IF(C10<0.3,"健康",IF(C10<0.45,"警惕","风险"))) -> 健康 | G10: =IF(C10="","",IF(C10<0.3,1,IF(C10<0.45,0,-1))) -> 1 | H10: Good news, bad reaction
A11: 情绪 | B11: 利空不跌比例 | C11: ='5_Price_Action'!B90 -> 0 | E11: >25%偏底部; <10%偏顶部 | F11: =IF(C11="","",IF(C11>0.25,"偏底部",IF(C11>0.1,"中性","偏顶部"))) -> 偏顶部 | G11: =IF(C11="","",IF(C11>0.25,1,IF(C11>0.1,0,-1))) -> -1 | H11: Bad news, good reaction
A12: 广度 | B12: 板块联动均值 | C12: ='5_Price_Action'!B91 | E12: >0.60广度好; 0.4-0.6一般; <0.4差 | F12: =IF(C12="","",IF(C12>0.6,"良好",IF(C12>0.4,"一般","较差"))) | G12: =IF(C12="","",IF(C12>0.6,1,IF(C12>0.4,0,-1))) | H12: 龙头带动板块
A14: 总分（-6 到 +6） | B14: =SUM(G6:G12) -> -1
A15: 流动性总分 | B15: =SUM(G6:G8) -> -2
A16: 业绩/基本面得分 | B16: =G9 -> 1
A17: 市场状态（矩阵输出） | B17: =_xlfn.LET(_xlpm.liq,B15,_xlpm.fund,B16,_xlpm.liqState,IF(_xlpm.liq>=2,"宽松",IF(_xlpm.liq<=0,"收紧","中性")),IF(AND(_xlpm.liqState="宽松",_xlpm.fund=1),"主升浪",IF(AND(_xlpm.liqState="宽松",_xlpm.fund<=0),"震荡",IF(AND(_xlpm.liqState="收紧",_xlpm.fund=1),"分化","双杀")))) -> #NAME?
A19: 使用说明（快速）
A20: 1) 先在 Sheet1/2/3 填宏观与流动性；2) Sheet4 填Mag7财报核心数字；3) Sheet5 记录“利好不涨/利空不跌”；4) 回到本页看总分与市场状态。
D32: https://api.stlouisfed.org/fred/series/observations, API is 216cc2c0220dedeb572e8649f7a0ff0a, 通过美联储的数据来用

Sheet 1_Macro_Liquidity
A1: 宏观流动性（美联储与点阵图）
A2: 输入每次FOMC更新后的关键数字；用“评分”给宏观方向打分（+1/0/-1）。
A3: 更新日期（本行） | B3: 2026-02-10
A5: 指标 | B5: 最新值(输入) | C5: 上次值(输入) | D5: 变化(公式) | E5: 阈值/参考(输入) | F5: 评分(公式) | G5: 解读/备注 | H5: 数据来源(可选)
A6: 2026年末点阵图中值(%) | D6: =IF(OR(B6="",C6=""),"",B6-C6) | E6: 下降→偏鸽 | F6: =IF(B6="","",IF(D6<0,1,IF(D6>0,-1,0))) | G6: 关注“降到哪”而非“降多少”
A7: 长期中性利率(%) | D7: =IF(OR(B7="",C7=""),"",B7-C7) | E7: 锚点 | F7: =IF(B7="","",IF(D7>0,-1,IF(D7<0,1,0))) | G7: 中性利率若上修→估值中枢下移风险
A8: 预计不降息官员数 | D8: =IF(OR(B8="",C8=""),"",B8-C8) | E8: 分歧 | F8: =IF(B8="","",IF(D8>0,-1,IF(D8<0,1,0))) | G8: 人数上升→政策不确定性↑
A9: 主席更替/政策不确定性(0-2) | D9: =IF(OR(B9="",C9=""),"",B9-C9) | E9: 0低 1中 2高 | F9: =IF(B9="","",IF(B9>=2,-1,IF(B9=1,0,1))) | G9: 换届年可上调风险折价
G11: 宏观政策得分（合计） | H11: =SUM(F6:F9) -> 0

Sheet 2_RealRate_Valuation
A1: 实际利率与估值（Real Rate）
A2: 输入10Y TIPS（实际利率）与指数表现，用阈值判断成长股估值环境。
A3: 分母端压力： 当 TIPS $> 1.5\%$ 时，折现率（Discount Rate）明显上升，意味着同样的利润，在今天值更少的钱。估值约束： 历史经验表明，当 10 年期 TIPS 每上升 50 个基点（0.5%），在盈利预期不变的情况下，标普 500 的理论市盈率（P/E）会面临 5%-10% 的修正压力。2026 年现状： 目前 TIPS 在 1.8% - 2.0% 附近震荡，属于**“紧缩区间”的边缘**。这意味着目前美股的上涨完全是由“业绩增长（E）”拉动的，而非“估值扩张（P/E）”。
A5: 日期 | B5: 10Y TIPS(%) 输入 | C5: 1M前 输入 | D5: 变化(公式) | E5: 阈值上限(%) 输入 | F5: 评分(公式) | G5: 备注 | H5: 来源
A6: =INDEX(pq_tips_dfii10!$A:$A,COUNT(pq_tips_dfii10!$A:$A)-34+ROW()) -> 46031 | B6: =VLOOKUP(A6,查询1[],2,FALSE) -> 1.9 | C6: =VLOOKUP(I6,查询1[],2,FALSE) -> 1.92 | D6: =IF(OR(B6="",C6=""),"",B6-C6) -> -0.02 | E6: 1.5 | F6: =IF(B6="","",IF(B6<=E6,1,IF(B6<=E6+0.25,0,-1))) -> -1 | I6: =[1]!TDaysOffset(A6,"Period=M","Offset=-1") -> 46000
A7: =INDEX(pq_tips_dfii10!$A:$A,COUNT(pq_tips_dfii10!$A:$A)-34+ROW()) -> 46034 | B7: =VLOOKUP(A7,查询1[],2,FALSE) -> 1.9 | C7: =VLOOKUP(I7,查询1[],2,FALSE) -> 1.93 | D7: =IF(OR(B7="",C7=""),"",B7-C7) -> -0.03 | E7: 1.5 | F7: =IF(B7="","",IF(B7<=E7,1,IF(B7<=E7+0.25,0,-1))) -> -1 | I7: =[1]!TDaysOffset(A7,"Period=M","Offset=-1") -> 46003
A8: =INDEX(pq_tips_dfii10!$A:$A,COUNT(pq_tips_dfii10!$A:$A)-34+ROW()) -> 46035 | B8: =VLOOKUP(A8,查询1[],2,FALSE) -> 1.88 | C8: =VLOOKUP(I8,查询1[],2,FALSE) -> 1.93 | D8: =IF(OR(B8="",C8=""),"",B8-C8) -> -0.05 | E8: 1.5 | F8: =IF(B8="","",IF(B8<=E8,1,IF(B8<=E8+0.25,0,-1))) -> -1 | I8: =[1]!TDaysOffset(A8,"Period=M","Offset=-1") -> 46003
A9: =INDEX(pq_tips_dfii10!$A:$A,COUNT(pq_tips_dfii10!$A:$A)-34+ROW()) -> 46036 | B9: =VLOOKUP(A9,查询1[],2,FALSE) -> 1.86 | C9: =VLOOKUP(I9,查询1[],2,FALSE) -> 1.93 | D9: =IF(OR(B9="",C9=""),"",B9-C9) -> -0.07 | E9: 1.5 | F9: =IF(B9="","",IF(B9<=E9,1,IF(B9<=E9+0.25,0,-1))) -> -1 | I9: =[1]!TDaysOffset(A9,"Period=M","Offset=-1") -> 46003
A10: =INDEX(pq_tips_dfii10!$A:$A,COUNT(pq_tips_dfii10!$A:$A)-34+ROW()) -> 46037 | B10: =VLOOKUP(A10,查询1[],2,FALSE) -> 1.88 | C10: =VLOOKUP(I10,查询1[],2,FALSE) -> 1.93 | D10: =IF(OR(B10="",C10=""),"",B10-C10) -> -0.05 | E10: 1.5 | F10: =IF(B10="","",IF(B10<=E10,1,IF(B10<=E10+0.25,0,-1))) -> -1 | I10: =[1]!TDaysOffset(A10,"Period=M","Offset=-1") -> 46006
A11: =INDEX(pq_tips_dfii10!$A:$A,COUNT(pq_tips_dfii10!$A:$A)-34+ROW()) -> 46038 | B11: =VLOOKUP(A11,查询1[],2,FALSE) -> 1.91 | C11: =VLOOKUP(I11,查询1[],2,FALSE) -> 1.92 | D11: =IF(OR(B11="",C11=""),"",B11-C11) -> -0.01 | E11: 1.5 | F11: =IF(B11="","",IF(B11<=E11,1,IF(B11<=E11+0.25,0,-1))) -> -1 | I11: =[1]!TDaysOffset(A11,"Period=M","Offset=-1") -> 46007
A12: =INDEX(pq_tips_dfii10!$A:$A,COUNT(pq_tips_dfii10!$A:$A)-34+ROW()) -> 46042 | B12: =VLOOKUP(A12,查询1[],2,FALSE) -> 1.97 | C12: =VLOOKUP(I12,查询1[],2,FALSE) -> 1.92 | D12: =IF(OR(B12="",C12=""),"",B12-C12) -> 0.05 | E12: 1.5 | F12: =IF(B12="","",IF(B12<=E12,1,IF(B12<=E12+0.25,0,-1))) -> -1 | I12: =[1]!TDaysOffset(A12,"Period=M","Offset=-1") -> 46010
A13: =INDEX(pq_tips_dfii10!$A:$A,COUNT(pq_tips_dfii10!$A:$A)-34+ROW()) -> 46043 | B13: =VLOOKUP(A13,查询1[],2,FALSE) -> 1.92 | C13: =VLOOKUP(I13,查询1[],2,FALSE) -> 1.92 | D13: =IF(OR(B13="",C13=""),"",B13-C13) -> 0 | E13: 1.5 | F13: =IF(B13="","",IF(B13<=E13,1,IF(B13<=E13+0.25,0,-1))) -> -1 | I13: =[1]!TDaysOffset(A13,"Period=M","Offset=-1") -> 46010
A14: =INDEX(pq_tips_dfii10!$A:$A,COUNT(pq_tips_dfii10!$A:$A)-34+ROW()) -> 46044 | B14: =VLOOKUP(A14,查询1[],2,FALSE) -> 1.95 | C14: =VLOOKUP(I14,查询1[],2,FALSE) -> 1.94 | D14: =IF(OR(B14="",C14=""),"",B14-C14) -> 0.01 | E14: 1.5 | F14: =IF(B14="","",IF(B14<=E14,1,IF(B14<=E14+0.25,0,-1))) -> -1 | I14: =[1]!TDaysOffset(A14,"Period=M","Offset=-1") -> 46013
A15: =INDEX(pq_tips_dfii10!$A:$A,COUNT(pq_tips_dfii10!$A:$A)-34+ROW()) -> 46045 | B15: =VLOOKUP(A15,查询1[],2,FALSE) -> 1.92 | C15: =VLOOKUP(I15,查询1[],2,FALSE) -> 1.94 | D15: =IF(OR(B15="",C15=""),"",B15-C15) -> -0.02 | E15: 1.5 | F15: =IF(B15="","",IF(B15<=E15,1,IF(B15<=E15+0.25,0,-1))) -> -1 | I15: =[1]!TDaysOffset(A15,"Period=M","Offset=-1") -> 46014
A16: =INDEX(pq_tips_dfii10!$A:$A,COUNT(pq_tips_dfii10!$A:$A)-34+ROW()) -> 46048 | B16: =VLOOKUP(A16,查询1[],2,FALSE) -> 1.9 | C16: =VLOOKUP(I16,查询1[],2,FALSE) -> 1.91 | D16: =IF(OR(B16="",C16=""),"",B16-C16) -> -0.01 | E16: 1.5 | F16: =IF(B16="","",IF(B16<=E16,1,IF(B16<=E16+0.25,0,-1))) -> -1 | I16: =[1]!TDaysOffset(A16,"Period=M","Offset=-1") -> 46017
A17: =INDEX(pq_tips_dfii10!$A:$A,COUNT(pq_tips_dfii10!$A:$A)-34+ROW()) -> 46049 | B17: =VLOOKUP(A17,查询1[],2,FALSE) -> 1.9 | C17: =VLOOKUP(I17,查询1[],2,FALSE) -> 1.91 | D17: =IF(OR(B17="",C17=""),"",B17-C17) -> -0.01 | E17: 1.5 | F17: =IF(B17="","",IF(B17<=E17,1,IF(B17<=E17+0.25,0,-1))) -> -1 | I17: =[1]!TDaysOffset(A17,"Period=M","Offset=-1") -> 46017
... A35: =INDEX(pq_tips_dfii10!$A:$A,COUNT(pq_tips_dfii10!$A:$A)-34+ROW()) -> 46076 | B35: =VLOOKUP(A35,查询1[],2,FALSE) -> 1.77 | C35: =VLOOKUP(I35,查询1[],2,FALSE) -> 1.92 | D35: =IF(OR(B35="",C35=""),"",B35-C35) -> -0.15 | E35: 1.5 | F35: =IF(B35="","",IF(B35<=E35,1,IF(B35<=E35+0.25,0,-1))) -> -1 | I35: =[1]!TDaysOffset(A35,"Period=M","Offset=-1") -> 46045
A37: 实际利率得分（最近一行） | B37: =IFERROR(LOOKUP(2,1/(F6:F35<>""),F6:F35),"") -> -1

Sheet 3_TGA_RRP
A1: TGA 与 RRP（财政流动性）
A2: TGA下降=释放流动性；RRP见底时“弹性”通常更大。
A5: 日期 | B5: TGA(亿美元) 输入 | C5: 上期TGA 输入 | D5: TGA变化(公式) | E5: 目标余额(亿美元) 输入 | F5: 评分(公式) | G5: 备注 | H5: 来源
A6: =INDEX(pq_tga_wtregen!$A:$A,COUNT(pq_tga_wtregen!$A:$A)-34+ROW()) -> 45868 | B6: =VLOOKUP(A6,pq_tga_wtregen!$A:$B,2,FALSE) -> 3705.07 | D6: =IF(OR(B6="",C6=""),"",B6-C6) | E6: 8500 | F6: =IF(B6="","",IF(B6<=E6,1,IF(B6<=E6+300,0,-1))) -> 1
A7: =INDEX(pq_tga_wtregen!$A:$A,COUNT(pq_tga_wtregen!$A:$A)-34+ROW()) -> 45875 | B7: =VLOOKUP(A7,pq_tga_wtregen!$A:$B,2,FALSE) -> 4210.43 | D7: =IF(OR(B7="",C7=""),"",B7-C7) | E7: 8500 | F7: =IF(B7="","",IF(B7<=E7,1,IF(B7<=E7+300,0,-1))) -> 1
A8: =INDEX(pq_tga_wtregen!$A:$A,COUNT(pq_tga_wtregen!$A:$A)-34+ROW()) -> 45882 | B8: =VLOOKUP(A8,pq_tga_wtregen!$A:$B,2,FALSE) -> 5043.04 | D8: =IF(OR(B8="",C8=""),"",B8-C8) | E8: 8500 | F8: =IF(B8="","",IF(B8<=E8,1,IF(B8<=E8+300,0,-1))) -> 1
A9: =INDEX(pq_tga_wtregen!$A:$A,COUNT(pq_tga_wtregen!$A:$A)-34+ROW()) -> 45889 | B9: =VLOOKUP(A9,pq_tga_wtregen!$A:$B,2,FALSE) -> 5195.34 | D9: =IF(OR(B9="",C9=""),"",B9-C9) | E9: 8500 | F9: =IF(B9="","",IF(B9<=E9,1,IF(B9<=E9+300,0,-1))) -> 1
A10: =INDEX(pq_tga_wtregen!$A:$A,COUNT(pq_tga_wtregen!$A:$A)-34+ROW()) -> 45896 | B10: =VLOOKUP(A10,pq_tga_wtregen!$A:$B,2,FALSE) -> 5899.98 | D10: =IF(OR(B10="",C10=""),"",B10-C10) | E10: 8500 | F10: =IF(B10="","",IF(B10<=E10,1,IF(B10<=E10+300,0,-1))) -> 1
A11: =INDEX(pq_tga_wtregen!$A:$A,COUNT(pq_tga_wtregen!$A:$A)-34+ROW()) -> 45903 | B11: =VLOOKUP(A11,pq_tga_wtregen!$A:$B,2,FALSE) -> 5975.13 | D11: =IF(OR(B11="",C11=""),"",B11-C11) | E11: 8500 | F11: =IF(B11="","",IF(B11<=E11,1,IF(B11<=E11+300,0,-1))) -> 1
A12: =INDEX(pq_tga_wtregen!$A:$A,COUNT(pq_tga_wtregen!$A:$A)-34+ROW()) -> 45910 | B12: =VLOOKUP(A12,pq_tga_wtregen!$A:$B,2,FALSE) -> 6722.74 | D12: =IF(OR(B12="",C12=""),"",B12-C12) | E12: 8500 | F12: =IF(B12="","",IF(B12<=E12,1,IF(B12<=E12+300,0,-1))) -> 1
A13: =INDEX(pq_tga_wtregen!$A:$A,COUNT(pq_tga_wtregen!$A:$A)-34+ROW()) -> 45917 | B13: =VLOOKUP(A13,pq_tga_wtregen!$A:$B,2,FALSE) -> 7563.76 | D13: =IF(OR(B13="",C13=""),"",B13-C13) | E13: 8500 | F13: =IF(B13="","",IF(B13<=E13,1,IF(B13<=E13+300,0,-1))) -> 1
A14: =INDEX(pq_tga_wtregen!$A:$A,COUNT(pq_tga_wtregen!$A:$A)-34+ROW()) -> 45924 | B14: =VLOOKUP(A14,pq_tga_wtregen!$A:$B,2,FALSE) -> 8048.56 | D14: =IF(OR(B14="",C14=""),"",B14-C14) | E14: 8500 | F14: =IF(B14="","",IF(B14<=E14,1,IF(B14<=E14+300,0,-1))) -> 1
A15: =INDEX(pq_tga_wtregen!$A:$A,COUNT(pq_tga_wtregen!$A:$A)-34+ROW()) -> 45931 | B15: =VLOOKUP(A15,pq_tga_wtregen!$A:$B,2,FALSE) -> 8051.39 | D15: =IF(OR(B15="",C15=""),"",B15-C15) | E15: 8500 | F15: =IF(B15="","",IF(B15<=E15,1,IF(B15<=E15+300,0,-1))) -> 1
A16: =INDEX(pq_tga_wtregen!$A:$A,COUNT(pq_tga_wtregen!$A:$A)-34+ROW()) -> 45938 | B16: =VLOOKUP(A16,pq_tga_wtregen!$A:$B,2,FALSE) -> 8074.28 | D16: =IF(OR(B16="",C16=""),"",B16-C16) | E16: 8500 | F16: =IF(B16="","",IF(B16<=E16,1,IF(B16<=E16+300,0,-1))) -> 1
A17: =INDEX(pq_tga_wtregen!$A:$A,COUNT(pq_tga_wtregen!$A:$A)-34+ROW()) -> 45945 | B17: =VLOOKUP(A17,pq_tga_wtregen!$A:$B,2,FALSE) -> 8095.93 | D17: =IF(OR(B17="",C17=""),"",B17-C17) | E17: 8500 | F17: =IF(B17="","",IF(B17<=E17,1,IF(B17<=E17+300,0,-1))) -> 1
... A35: =INDEX(pq_tga_wtregen!$A:$A,COUNT(pq_tga_wtregen!$A:$A)-34+ROW()) -> 46071 | B35: =VLOOKUP(A35,pq_tga_wtregen!$A:$B,2,FALSE) -> 9127.27 | D35: =IF(OR(B35="",C35=""),"",B35-C35) | E35: 8500 | F35: =IF(B35="","",IF(B35<=E35,1,IF(B35<=E35+300,0,-1))) -> -1
A37: RRP监控（可选）
A38: 日期 | B38: RRP(亿美元) 输入 | C38: 上期RRP 输入 | D38: RRP变化(公式) | E38: “见底”阈值(亿美元) 输入 | F38: 评分(公式) | G38: 备注 | H38: 来源
A39: =INDEX(pq_rrp_rrpontsyd!$A:$A,COUNT(pq_rrp_rrpontsyd!$A:$A)-20+ROW()-37) -> 46049 | B39: =VLOOKUP(A39,查询3[#All],2,FALSE) -> 1.253e-08 | D39: =IF(OR(B39="",C39=""),"",B39-C39) | E39: 1000 | F39: =IF(B39="","",IF(B39<=E39,1,0)) -> 1
A40: =INDEX(pq_rrp_rrpontsyd!$A:$A,COUNT(pq_rrp_rrpontsyd!$A:$A)-20+ROW()-37) -> 46050 | B40: =VLOOKUP(A40,查询3[#All],2,FALSE) -> 1.103e-08 | D40: =IF(OR(B40="",C40=""),"",B40-C40) | E40: 1000 | F40: =IF(B40="","",IF(B40<=E40,1,0)) -> 1
A41: =INDEX(pq_rrp_rrpontsyd!$A:$A,COUNT(pq_rrp_rrpontsyd!$A:$A)-20+ROW()-37) -> 46051 | B41: =VLOOKUP(A41,查询3[#All],2,FALSE) -> 2.852e-08 | D41: =IF(OR(B41="",C41=""),"",B41-C41) | E41: 1000 | F41: =IF(B41="","",IF(B41<=E41,1,0)) -> 1
A42: =INDEX(pq_rrp_rrpontsyd!$A:$A,COUNT(pq_rrp_rrpontsyd!$A:$A)-20+ROW()-37) -> 46052 | B42: =VLOOKUP(A42,查询3[#All],2,FALSE) -> 9.629e-08 | D42: =IF(OR(B42="",C42=""),"",B42-C42) | E42: 1000 | F42: =IF(B42="","",IF(B42<=E42,1,0)) -> 1
A43: =INDEX(pq_rrp_rrpontsyd!$A:$A,COUNT(pq_rrp_rrpontsyd!$A:$A)-20+ROW()-37) -> 46055 | B43: =VLOOKUP(A43,查询3[#All],2,FALSE) -> 1.0415e-07 | D43: =IF(OR(B43="",C43=""),"",B43-C43) | E43: 1000 | F43: =IF(B43="","",IF(B43<=E43,1,0)) -> 1
A44: =INDEX(pq_rrp_rrpontsyd!$A:$A,COUNT(pq_rrp_rrpontsyd!$A:$A)-20+ROW()-37) -> 46056 | B44: =VLOOKUP(A44,查询3[#All],2,FALSE) -> 1.785e-08 | D44: =IF(OR(B44="",C44=""),"",B44-C44) | E44: 1000 | F44: =IF(B44="","",IF(B44<=E44,1,0)) -> 1
A45: =INDEX(pq_rrp_rrpontsyd!$A:$A,COUNT(pq_rrp_rrpontsyd!$A:$A)-20+ROW()-37) -> 46057 | B45: =VLOOKUP(A45,查询3[#All],2,FALSE) -> 2.414e-08 | D45: =IF(OR(B45="",C45=""),"",B45-C45) | E45: 1000 | F45: =IF(B45="","",IF(B45<=E45,1,0)) -> 1
A46: =INDEX(pq_rrp_rrpontsyd!$A:$A,COUNT(pq_rrp_rrpontsyd!$A:$A)-20+ROW()-37) -> 46058 | B46: =VLOOKUP(A46,查询3[#All],2,FALSE) -> 1.748e-08 | D46: =IF(OR(B46="",C46=""),"",B46-C46) | E46: 1000 | F46: =IF(B46="","",IF(B46<=E46,1,0)) -> 1
A47: =INDEX(pq_rrp_rrpontsyd!$A:$A,COUNT(pq_rrp_rrpontsyd!$A:$A)-20+ROW()-37) -> 46059 | B47: =VLOOKUP(A47,查询3[#All],2,FALSE) -> 3.111e-08 | D47: =IF(OR(B47="",C47=""),"",B47-C47) | E47: 1000 | F47: =IF(B47="","",IF(B47<=E47,1,0)) -> 1
A48: =INDEX(pq_rrp_rrpontsyd!$A:$A,COUNT(pq_rrp_rrpontsyd!$A:$A)-20+ROW()-37) -> 46062 | B48: =VLOOKUP(A48,查询3[#All],2,FALSE) -> 1.306e-08 | D48: =IF(OR(B48="",C48=""),"",B48-C48) | E48: 1000 | F48: =IF(B48="","",IF(B48<=E48,1,0)) -> 1
A49: =INDEX(pq_rrp_rrpontsyd!$A:$A,COUNT(pq_rrp_rrpontsyd!$A:$A)-20+ROW()-37) -> 46063 | B49: =VLOOKUP(A49,查询3[#All],2,FALSE) -> 1.447e-08 | D49: =IF(OR(B49="",C49=""),"",B49-C49) | E49: 1000 | F49: =IF(B49="","",IF(B49<=E49,1,0)) -> 1
A50: =INDEX(pq_rrp_rrpontsyd!$A:$A,COUNT(pq_rrp_rrpontsyd!$A:$A)-20+ROW()-37) -> 46064 | B50: =VLOOKUP(A50,查询3[#All],2,FALSE) -> 1.048e-08 | D50: =IF(OR(B50="",C50=""),"",B50-C50) | E50: 1000 | F50: =IF(B50="","",IF(B50<=E50,1,0)) -> 1
... A58: =INDEX(pq_rrp_rrpontsyd!$A:$A,COUNT(pq_rrp_rrpontsyd!$A:$A)-20+ROW()-37) -> 46077 | B58: =VLOOKUP(A58,查询3[#All],2,FALSE) -> 9.17e-09 | D58: =IF(OR(B58="",C58=""),"",B58-C58) | E58: 1000 | F58: =IF(B58="","",IF(B58<=E58,1,0)) -> 1

Sheet 4_Micro_Fundamentals
A1: 微观基本面（Mag 7）
A2: 每季财报后更新：EPS增速、AI占比、CapEx强度、利润率、FCF。用红线规则识别风险。 | K2: =MAX(IF(pq_fh_earnings!$A:$A=A6,pq_fh_earnings!$B:$B)) -> 46022
A3: 提示：成本增速 > 营收增速通常触发“杀估值”；利润率( Margin )指引更关键。
A5: Ticker | B5: 公司 | C5: EPS 输入 | D5: 预期EPS 输入 | E5: Surprise(公式) | F5: AI收入占比(%) 输入 | G5: CapEx/Rev(%) 输入 | H5: Margin YoY(pp) 输入 | I5: FCF YoY(%) 输入
A6: AAPL | B6: Apple | C6: {=INDEX(pq_fh_earnings!$C:$C, MATCH(1,(pq_fh_earnings!$A:$A=$A6)*(pq_fh_earnings!$B:$B=$K$2),0))} -> 2.84 | D6: {=INDEX(pq_fh_earnings!$D:$D, MATCH(1,(pq_fh_earnings!$A:$A=$A6)*(pq_fh_earnings!$B:$B=$K$2),0))} -> 2.7257 | E6: =IF(OR(C6="",D6=""),"",C6-D6) -> 0.1143 | G6: =VLOOKUP(A6,查询7[#All],8,FALSE) -> 0.016507137 | H6: =VLOOKUP(A6,pq_fh_financials!$A$1:$I$264,9,FALSE) -> 0.00055972311 | I6: =VLOOKUP(A6,查询7[#All],10,FALSE) -> 0.90968698
A7: MSFT | B7: Microsoft | C7: {=INDEX(pq_fh_earnings!$C:$C, MATCH(1,(pq_fh_earnings!$A:$A=$A7)*(pq_fh_earnings!$B:$B=$K$2),0))} -> 4.14 | D7: {=INDEX(pq_fh_earnings!$D:$D, MATCH(1,(pq_fh_earnings!$A:$A=$A7)*(pq_fh_earnings!$B:$B=$K$2),0))} -> 4.0345 | E7: =IF(OR(C7="",D7=""),"",C7-D7) -> 0.1055 | G7: =VLOOKUP(A7,查询7[#All],8,FALSE) -> 0.30997949 | H7: =VLOOKUP(A7,pq_fh_financials!$A$1:$I$264,9,FALSE) -> 0.055808631 | I7: =VLOOKUP(A7,查询7[#All],10,FALSE) -> 0.22533406
A8: NVDA | B8: NVIDIA | C8: {=INDEX(pq_fh_earnings!$C:$C, MATCH(1,(pq_fh_earnings!$A:$A=$A8)*(pq_fh_earnings!$B:$B=$K$2),0))} -> 1.3 | D8: {=INDEX(pq_fh_earnings!$D:$D, MATCH(1,(pq_fh_earnings!$A:$A=$A8)*(pq_fh_earnings!$B:$B=$K$2),0))} -> 1.2746 | E8: =IF(OR(C8="",D8=""),"",C8-D8) -> 0.0254 | G8: =VLOOKUP(A8,查询7[#All],8,FALSE) -> 0.032189756 | H8: =VLOOKUP(A8,pq_fh_financials!$A$1:$I$264,9,FALSE) -> -0.035445206 | I8: =VLOOKUP(A8,查询7[#All],10,FALSE) -> 0.36359021
A9: GOOGL | B9: Alphabet | C9: {=INDEX(pq_fh_earnings!$C:$C, MATCH(1,(pq_fh_earnings!$A:$A=$A9)*(pq_fh_earnings!$B:$B=$K$2),0))} -> 2.82 | D9: {=INDEX(pq_fh_earnings!$D:$D, MATCH(1,(pq_fh_earnings!$A:$A=$A9)*(pq_fh_earnings!$B:$B=$K$2),0))} -> 2.7063 | E9: =IF(OR(C9="",D9=""),"",C9-D9) -> 0.1137 | G9: =VLOOKUP(A9,查询7[#All],8,FALSE) -> 0.22005003 | H9: =VLOOKUP(A9,pq_fh_financials!$A$1:$I$264,9,FALSE) -> 0.047897793 | I9: =VLOOKUP(A9,查询7[#All],10,FALSE) -> 0.016441672
A10: AMZN | B10: Amazon | C10: {=INDEX(pq_fh_earnings!$C:$C, MATCH(1,(pq_fh_earnings!$A:$A=$A10)*(pq_fh_earnings!$B:$B=$K$2),0))} -> 1.95 | D10: {=INDEX(pq_fh_earnings!$D:$D, MATCH(1,(pq_fh_earnings!$A:$A=$A10)*(pq_fh_earnings!$B:$B=$K$2),0))} -> 2.011 | E10: =IF(OR(C10="",D10=""),"",C10-D10) -> -0.061 | G10: =VLOOKUP(A10,查询7[#All],8,FALSE) -> 0.18329699 | H10: =VLOOKUP(A10,pq_fh_financials!$A$1:$I$264,9,FALSE) -> 0.030058594 | I10: =VLOOKUP(A10,查询7[#All],10,FALSE) -> -1.6176546
A11: META | B11: Meta | C11: {=INDEX(pq_fh_earnings!$C:$C, MATCH(1,(pq_fh_earnings!$A:$A=$A11)*(pq_fh_earnings!$B:$B=$K$2),0))} -> 8.88 | D11: {=INDEX(pq_fh_earnings!$D:$D, MATCH(1,(pq_fh_earnings!$A:$A=$A11)*(pq_fh_earnings!$B:$B=$K$2),0))} -> 8.3992 | E11: =IF(OR(C11="",D11=""),"",C11-D11) -> 0.4808 | G11: =VLOOKUP(A11,查询7[#All],8,FALSE) -> 0.34243264 | H11: =VLOOKUP(A11,pq_fh_financials!$A$1:$I$264,9,FALSE) -> -0.090424041 | I11: =VLOOKUP(A11,查询7[#All],10,FALSE) -> -0.22787529
A12: TSLA | B12: Tesla | C12: {=INDEX(pq_fh_earnings!$C:$C, MATCH(1,(pq_fh_earnings!$A:$A=$A12)*(pq_fh_earnings!$B:$B=$K$2),0))} -> 0.5 | D12: {=INDEX(pq_fh_earnings!$D:$D, MATCH(1,(pq_fh_earnings!$A:$A=$A12)*(pq_fh_earnings!$B:$B=$K$2),0))} -> 0.4559 | E12: =IF(OR(C12="",D12=""),"",C12-D12) -> 0.0441 | G12: =VLOOKUP(A12,查询7[#All],8,FALSE) -> 0.087721305 | H12: =VLOOKUP(A12,pq_fh_financials!$A$1:$I$264,9,FALSE) -> -0.024076556 | I12: =VLOOKUP(A12,查询7[#All],10,FALSE) -> 2.090792
A15: Mag7综合得分（按“超预期+利润率+FCF”粗略打分，可自行改权重）
A16: Ticker | B16: Surprise | C16: Margin QoQ | D16: FCF YoY | E16: 单股得分(公式) | F16: 权重(输入) | G16: 加权得分(公式) | H16: 备注
A17: AAPL | B17: =E6 -> 0.1143 | C17: =H6 -> 0.00055972311 | D17: =I6 -> 0.90968698 | E17: =IFERROR(SIGN((IF(B17>0,1,0)+IF(C17>0,1,0)+IF(D17>0,1,0))-1),"") -> 1 | F17: 0.1429 | G17: =IF(OR(E17="",F17=""),"",E17*F17) -> 0.1429
A18: MSFT | B18: =E7 -> 0.1055 | C18: =H7 -> 0.055808631 | D18: =I7 -> 0.22533406 | E18: =IFERROR(SIGN((IF(B18>0,1,0)+IF(C18>0,1,0)+IF(D18>0,1,0))-1),"") -> 1 | F18: 0.1429 | G18: =IF(OR(E18="",F18=""),"",E18*F18) -> 0.1429
A19: NVDA | B19: =E8 -> 0.0254 | C19: =H8 -> -0.035445206 | D19: =I8 -> 0.36359021 | E19: =IFERROR(SIGN((IF(B19>0,1,0)+IF(C19>0,1,0)+IF(D19>0,1,0))-1),"") -> 1 | F19: 0.1429 | G19: =IF(OR(E19="",F19=""),"",E19*F19) -> 0.1429
A20: GOOGL | B20: =E9 -> 0.1137 | C20: =H9 -> 0.047897793 | D20: =I9 -> 0.016441672 | E20: =IFERROR(SIGN((IF(B20>0,1,0)+IF(C20>0,1,0)+IF(D20>0,1,0))-1),"") -> 1 | F20: 0.1429 | G20: =IF(OR(E20="",F20=""),"",E20*F20) -> 0.1429
A21: AMZN | B21: =E10 -> -0.061 | C21: =H10 -> 0.030058594 | D21: =I10 -> -1.6176546 | E21: =IFERROR(SIGN((IF(B21>0,1,0)+IF(C21>0,1,0)+IF(D21>0,1,0))-1),"") -> 0 | F21: 0.1429 | G21: =IF(OR(E21="",F21=""),"",E21*F21) -> 0
A22: META | B22: =E11 -> 0.4808 | C22: =H11 -> -0.090424041 | D22: =I11 -> -0.22787529 | E22: =IFERROR(SIGN((IF(B22>0,1,0)+IF(C22>0,1,0)+IF(D22>0,1,0))-1),"") -> 0 | F22: 0.1429 | G22: =IF(OR(E22="",F22=""),"",E22*F22) -> 0
A23: TSLA | B23: =E12 -> 0.0441 | C23: =H12 -> -0.024076556 | D23: =I12 -> 2.090792 | E23: =IFERROR(SIGN((IF(B23>0,1,0)+IF(C23>0,1,0)+IF(D23>0,1,0))-1),"") -> 1 | F23: 0.1429 | G23: =IF(OR(E23="",F23=""),"",E23*F23) -> 0.1429
F24: 权重合计 | G24: =SUM(F17:F23) -> 1.0003
F25: Mag7得分（加权） | G25: =SUM(G17:G23) -> 0.7145
K28: 46022

Sheet 5_Price_Action
A1: 价格行动（财报后反应）
A2: 记录“利好不涨 / 利空不跌”频率与板块联动性，用作牛熊转换最敏感信号。
A5: 日期 | B5: Ticker | C5: EPS结果 | D5: 指引结果 | E5: 开盘反应 | F5: 收盘反应 | G5: 类型(公式) | H5: 板块联动(0-1) 输入 | I5: 备注
G6: =IF(OR(C6="",F6=""),"",IF(AND(OR(C6="Beat",D6="上修"),OR(F6="回落",F6="收跌")),"利好不涨",IF(AND(OR(C6="Miss",D6="下修"),OR(F6="反弹",F6="震荡")),"利空不跌","正常")))
G7: =IF(OR(C7="",F7=""),"",IF(AND(OR(C7="Beat",D7="上修"),OR(F7="回落",F7="收跌")),"利好不涨",IF(AND(OR(C7="Miss",D7="下修"),OR(F7="反弹",F7="震荡")),"利空不跌","正常")))
G8: =IF(OR(C8="",F8=""),"",IF(AND(OR(C8="Beat",D8="上修"),OR(F8="回落",F8="收跌")),"利好不涨",IF(AND(OR(C8="Miss",D8="下修"),OR(F8="反弹",F8="震荡")),"利空不跌","正常")))
G9: =IF(OR(C9="",F9=""),"",IF(AND(OR(C9="Beat",D9="上修"),OR(F9="回落",F9="收跌")),"利好不涨",IF(AND(OR(C9="Miss",D9="下修"),OR(F9="反弹",F9="震荡")),"利空不跌","正常")))
G10: =IF(OR(C10="",F10=""),"",IF(AND(OR(C10="Beat",D10="上修"),OR(F10="回落",F10="收跌")),"利好不涨",IF(AND(OR(C10="Miss",D10="下修"),OR(F10="反弹",F10="震荡")),"利空不跌","正常")))
G11: =IF(OR(C11="",F11=""),"",IF(AND(OR(C11="Beat",D11="上修"),OR(F11="回落",F11="收跌")),"利好不涨",IF(AND(OR(C11="Miss",D11="下修"),OR(F11="反弹",F11="震荡")),"利空不跌","正常")))
G12: =IF(OR(C12="",F12=""),"",IF(AND(OR(C12="Beat",D12="上修"),OR(F12="回落",F12="收跌")),"利好不涨",IF(AND(OR(C12="Miss",D12="下修"),OR(F12="反弹",F12="震荡")),"利空不跌","正常")))
G13: =IF(OR(C13="",F13=""),"",IF(AND(OR(C13="Beat",D13="上修"),OR(F13="回落",F13="收跌")),"利好不涨",IF(AND(OR(C13="Miss",D13="下修"),OR(F13="反弹",F13="震荡")),"利空不跌","正常")))
G14: =IF(OR(C14="",F14=""),"",IF(AND(OR(C14="Beat",D14="上修"),OR(F14="回落",F14="收跌")),"利好不涨",IF(AND(OR(C14="Miss",D14="下修"),OR(F14="反弹",F14="震荡")),"利空不跌","正常")))
G15: =IF(OR(C15="",F15=""),"",IF(AND(OR(C15="Beat",D15="上修"),OR(F15="回落",F15="收跌")),"利好不涨",IF(AND(OR(C15="Miss",D15="下修"),OR(F15="反弹",F15="震荡")),"利空不跌","正常")))
G16: =IF(OR(C16="",F16=""),"",IF(AND(OR(C16="Beat",D16="上修"),OR(F16="回落",F16="收跌")),"利好不涨",IF(AND(OR(C16="Miss",D16="下修"),OR(F16="反弹",F16="震荡")),"利空不跌","正常")))
G17: =IF(OR(C17="",F17=""),"",IF(AND(OR(C17="Beat",D17="上修"),OR(F17="回落",F17="收跌")),"利好不涨",IF(AND(OR(C17="Miss",D17="下修"),OR(F17="反弹",F17="震荡")),"利空不跌","正常")))
... G85: =IF(OR(C85="",F85=""),"",IF(AND(OR(C85="Beat",D85="上修"),OR(F85="回落",F85="收跌")),"利好不涨",IF(AND(OR(C85="Miss",D85="下修"),OR(F85="反弹",F85="震荡")),"利空不跌","正常")))
A88: 统计（最近80条记录）
A89: 利好不涨比例 | B89: =IFERROR(COUNTIF(G6:G85,"利好不涨")/COUNTIF(G6:G85,"<>"),"") -> 0
A90: 利空不跌比例 | B90: =IFERROR(COUNTIF(G6:G85,"利空不跌")/COUNTIF(G6:G85,"<>"),"") -> 0
A91: 板块联动均值 | B91: =IFERROR(AVERAGEIF(H6:H85,">=0"),"")

Sheet 6_Data_API_PowerQuery
A1: 数据接口字段占位（FRED / 财政部）— 便于 PowerQuery 自动抓取
A2: 更新时间：2026-02-10 | 说明：本页只提供“接口字段占位 + 建议查询参数”，便于你在 PowerQuery 里复制粘贴并映射到各Sheet。
A4: A) FRED（宏观利率/通胀预期/流动性代理）
A5: 目标字段 | B5: 来源 | C5: Series ID / 数据集 | D5: Endpoint 模板 | E5: 关键参数占位 | F5: PowerQuery 目标表名 | G5: 刷新频率建议 | H5: 日期字段 | I5: 数值字段 | J5: 备注
A6: 联邦基金利率 | B6: FRED | C6: DFF | D6: https://api.stlouisfed.org/fred/series/observations?series_id={SERIES_ID}&api_key={FRED_API_KEY}&file_type=json&observation_start={START_DATE}&observation_end={END_DATE}&frequency={FREQ} | E6: {FRED_API_KEY}; {START_DATE}; {END_DATE}; FREQ=d | F6: pq_fedfunds_dff | G6: 日/周 | H6: date | I6: value | J6: 用于验证点阵图与市场定价偏离
A7: 10Y TIPS 实际利率 | B7: FRED | C7: DFII10 | D7: https://api.stlouisfed.org/fred/series/observations?series_id={SERIES_ID}&api_key={FRED_API_KEY}&file_type=json&observation_start={START_DATE}&observation_end={END_DATE}&frequency={FREQ} | E7: {FRED_API_KEY}; {START_DATE}; {END_DATE}; FREQ=d | F7: pq_tips_dfii10 | G7: 日/周 | H7: date | I7: value | J7: 用于Sheet2：实际利率阈值(0.50–0.75%)
A8: 10Y 通胀预期（Breakeven） | B8: FRED | C8: T10YIE | D8: https://api.stlouisfed.org/fred/series/observations?series_id={SERIES_ID}&api_key={FRED_API_KEY}&file_type=json&observation_start={START_DATE}&observation_end={END_DATE}&frequency={FREQ} | E8: {FRED_API_KEY}; {START_DATE}; {END_DATE}; FREQ=d | F8: pq_breakeven_t10yie | G8: 日/周 | H8: date | I8: value | J8: 名义-实际的隐含通胀预期
A9: 财政部一般账户TGA（代理） | B9: FRED | C9: WTREGEN | D9: https://api.stlouisfed.org/fred/series/observations?series_id={SERIES_ID}&api_key={FRED_API_KEY}&file_type=json&observation_start={START_DATE}&observation_end={END_DATE}&frequency={FREQ} | E9: {FRED_API_KEY}; {START_DATE}; {END_DATE}; FREQ=w | F9: pq_tga_wtregen | G9: 周 | H9: date | I9: value | J9: 用于Sheet3：TGA监控（注意单位/口径）
A10: 隔夜逆回购 ON RRP | B10: FRED | C10: RRPONTSYD | D10: https://api.stlouisfed.org/fred/series/observations?series_id={SERIES_ID}&api_key={FRED_API_KEY}&file_type=json&observation_start={START_DATE}&observation_end={END_DATE}&frequency={FREQ} | E10: {FRED_API_KEY}; {START_DATE}; {END_DATE}; FREQ=d | F10: pq_rrp_rrpontsyd | G10: 日/周 | H10: date | I10: value | J10: 用于Sheet3：RRP见底信号
A13: B) 美国财政部 Fiscal Data API（财政部官网接口，用于TGA/现金收支等更细口径）
A14: 目标字段 | B14: 来源 | C14: 数据集 / 路径占位 | D14: Endpoint 模板 | E14: 关键参数占位 | F14: PowerQuery 目标表名 | G14: 刷新频率建议 | H14: 日期字段 | I14: 数值字段 | J14: 备注
A15: TGA 余额（官方口径） | B15: Treasury Fiscal Data | C15: {PATH} 例如: account_balances/operating_cash_balance | D15: https://api.fiscaldata.treasury.gov/services/api/fiscal_service/v2/{PATH}?filter={FILTER}&fields={FIELDS}&sort={SORT}&page[number]={PAGE_NO}&page[size]={PAGE_SIZE} | E15: {PATH}; FILTER=record_date:gte:{START_DATE},record_date:lte:{END_DATE}; FIELDS=record_date,open_today_bal; SORT=record_date | F15: pq_tga_treasury_official | G15: 日/周 | H15: record_date | I15: open_today_bal | J15: 不同数据集字段名可能略有差异：在PQ里先预览再改FIELDS
A16: 财政部现金收支（可选） | B16: Treasury Fiscal Data | C16: {PATH} 例如: federal_accounting/operating_cash_balance 或 DTS相关数据集 | D16: https://api.fiscaldata.treasury.gov/services/api/fiscal_service/v2/{PATH}?filter={FILTER}&fields={FIELDS}&sort={SORT}&page[number]={PAGE_NO}&page[size]={PAGE_SIZE} | E16: {PATH}; FILTER=...; FIELDS=...; SORT=... | F16: pq_treasury_cashflow_optional | G16: 周/月 | H16: record_date | I16: value | J16: 用于解释TGA变动背后：发债/支出节奏
A19: C) 映射到本模板各Sheet的建议（PowerQuery加载后“表→单元格”引用）
A20: 目标Sheet | B20: 字段映射 | C20: 建议做法
A21: Sheet2_RealRate_Valuation | B21: 10Y TIPS(%) ← pq_tips_dfii10[value]（按日期匹配/最新值） | C21: 把“最新值”写入B列；日期写入A列；可用PQ直接生成两列表后粘贴为值或连接表格。
A22: Sheet3_TGA_RRP | B22: TGA(亿美元) ← pq_tga_wtregen 或 pq_tga_treasury_official（注意单位换算） | C22: 建议在PQ里先把单位统一成“亿美元”，再加载到Sheet3。
A23: Sheet3_TGA_RRP | B23: RRP(亿美元) ← pq_rrp_rrpontsyd[value]（注意单位） | C23: RRP常以美元计，建议PQ里/1e8转换为亿美元。
A24: Sheet1_Macro_Liquidity | B24: 联邦基金利率 ← pq_fedfunds_dff[value]（辅助监控） | C24: 点阵图仍需要手动更新，但可用联邦基金利率校验“实际路径”。
A26: D) PowerQuery快速步骤（复制到你团队文档也行）
A27: 1) Excel → 数据(Data) → 获取数据(Get Data) → 从其他源(From Other Sources) → 空白查询(Blank Query) 2) 在高级编辑器(Advanced Editor)中粘贴 Web.Contents(...) 的URL（上面黄色单元格里的模板） 3) 解析 JSON：转为表 → 展开 data/observations → 选择 date/value 字段 4) 类型转换：date→日期，value→数字；必要时过滤 '.' 或空值 5) 单位统一：例如 RRP/TGA 换算为“亿美元” 6) 加载为表到工作簿：表名建议使用 pq_* 前缀 7) Dashboard 用链接引用这些表的最新值（LOOKUP/INDEX/MATCH）或直接在各Sheet把表“粘贴为值” 提示：FRED 需要 FRED_API_KEY；财政部 Fiscal Data API 一般不需要 Key。

Sheet pq_fh_financials
A1: symbol | B1: period | C1: revenue | D1: capex | E1: free_cash_flow | F1: net_profit_margin | G1: rank | H1: Capex/Rev | I1: net_profit_margin_yoy | J1: Free_cash_flow_YOY | K1: 列1
A2: AAPL | B2: 46018 | C2: 143756000000 | D2: 2373000000 | E2: 51552000000 | F2: 0.29283647 | G2: 1 | H2: =查询7[[#This Row],[capex]]/查询7[[#This Row],[revenue]] -> 0.016507137 | I2: =查询7[[#This Row],[net_profit_margin]]-F5 -> 0.00055972311 | J2: =查询7[[#This Row],[free_cash_flow]]/E5-1 -> 0.90968698 | K2: =查询7[[#This Row],[free_cash_flow]]/E5-1 -> 0.90968698
A3: AAPL | B3: 45836 | C3: 313695000000 | D3: 9473000000 | E3: 72281000000 | F3: 0.26951019 | G3: 2 | H3: =查询7[[#This Row],[capex]]/查询7[[#This Row],[revenue]] -> 0.030198122 | I3: =查询7[[#This Row],[net_profit_margin]]-F6 -> 0.002712942 | J3: =查询7[[#This Row],[free_cash_flow]]/E6-1 -> -0.1486738 | K3: =查询7[[#This Row],[free_cash_flow]]/E6-1 -> -0.1486738
A4: AAPL | B4: 45745 | C4: 219659000000 | D4: 6011000000 | E4: 47876000000 | F4: 0.27820394 | G4: 3 | H4: =查询7[[#This Row],[capex]]/查询7[[#This Row],[revenue]] -> 0.027365143 | I4: =查询7[[#This Row],[net_profit_margin]]-F7 -> 0.0045741842 | J4: =查询7[[#This Row],[free_cash_flow]]/E7-1 -> -0.17734591 | K4: =查询7[[#This Row],[free_cash_flow]]/E7-1 -> -0.17734591
A5: AAPL | B5: 45654 | C5: 124300000000 | D5: 2940000000 | E5: 26995000000 | F5: 0.29227675 | G5: 4 | H5: =查询7[[#This Row],[capex]]/查询7[[#This Row],[revenue]] -> 0.023652454 | I5: =查询7[[#This Row],[net_profit_margin]]-F8 -> 0.0086388656 | J5: =查询7[[#This Row],[free_cash_flow]]/E8-1 -> -0.28019092 | K5: =查询7[[#This Row],[free_cash_flow]]/E8-1 -> -0.28019092
A6: AAPL | B6: 45472 | C6: 296105000000 | D6: 6539000000 | E6: 84904000000 | F6: 0.26679725 | G6: 5 | H6: =查询7[[#This Row],[capex]]/查询7[[#This Row],[revenue]] -> 0.022083383 | I6: =查询7[[#This Row],[net_profit_margin]]-F9 -> 0.014781335 | J6: =查询7[[#This Row],[free_cash_flow]]/E9-1 -> 0.059327003 | K6: =查询7[[#This Row],[free_cash_flow]]/E9-1 -> 0.059327003
A7: AAPL | B7: 45381 | C7: 210328000000 | D7: 4388000000 | E7: 58197000000 | F7: 0.27362976 | G7: 6 | H7: =查询7[[#This Row],[capex]]/查询7[[#This Row],[revenue]] -> 0.020862653 | I7: =查询7[[#This Row],[net_profit_margin]]-F10 -> 0.018155444 | J7: =查询7[[#This Row],[free_cash_flow]]/E10-1 -> 0.041799434 | K7: =查询7[[#This Row],[free_cash_flow]]/E10-1 -> 0.041799434
A8: AAPL | B8: 45290 | C8: 119575000000 | D8: 2392000000 | E8: 37503000000 | F8: 0.28363788 | G8: 7 | H8: =查询7[[#This Row],[capex]]/查询7[[#This Row],[revenue]] -> 0.020004181 | I8: =查询7[[#This Row],[net_profit_margin]]-F11 -> 0.027581753 | J8: =查询7[[#This Row],[free_cash_flow]]/E11-1 -> 0.24108147 | K8: =查询7[[#This Row],[free_cash_flow]]/E11-1 -> 0.24108147
A9: AAPL | B9: 45108 | C9: 293787000000 | D9: 8796000000 | E9: 80149000000 | F9: 0.25201592 | G9: 8 | H9: =查询7[[#This Row],[capex]]/查询7[[#This Row],[revenue]] -> 0.029940059 | I9: =查询7[[#This Row],[net_profit_margin]]-F12 -> -0.0079665942 | J9: =查询7[[#This Row],[free_cash_flow]]/E12-1 -> -0.11540202 | K9: =查询7[[#This Row],[free_cash_flow]]/E12-1 -> -0.11540202
A10: AAPL | B10: 45017 | C10: 211990000000 | D10: 6703000000 | E10: 55862000000 | F10: 0.25547431 | G10: 9 | H10: =查询7[[#This Row],[capex]]/查询7[[#This Row],[revenue]] -> 0.031619416 | I10: =查询7[[#This Row],[net_profit_margin]]-F13 -> -0.014117907 | J10: =查询7[[#This Row],[free_cash_flow]]/E13-1 -> -0.19985676 | K10: =查询7[[#This Row],[free_cash_flow]]/E13-1 -> -0.19985676
A11: AAPL | B11: 44926 | C11: 117154000000 | D11: 3787000000 | E11: 30218000000 | F11: 0.25605613 | G11: 10 | H11: =查询7[[#This Row],[capex]]/查询7[[#This Row],[revenue]] -> 0.032324974 | I11: =查询7[[#This Row],[net_profit_margin]]-F14 -> -0.023341989 | J11: =查询7[[#This Row],[free_cash_flow]]/E14-1 -> -0.31576206 | K11: =查询7[[#This Row],[free_cash_flow]]/E14-1 -> -0.31576206
A12: AAPL | B12: 44737 | C12: 304182000000 | D12: 7419000000 | E12: 90605000000 | F12: 0.25998251 | G12: 11 | H12: =查询7[[#This Row],[capex]]/查询7[[#This Row],[revenue]] -> 0.024390003 | I12: =查询7[[#This Row],[net_profit_margin]]-F15 -> -0.0024609765 | J12: =查询7[[#This Row],[free_cash_flow]]/E15-1 -> 0.19254765 | K12: =查询7[[#This Row],[free_cash_flow]]/E15-1 -> 0.19254765
A13: AAPL | B13: 44646 | C13: 221223000000 | D13: 5317000000 | E13: 69815000000 | F13: 0.26959222 | G13: 12 | H13: =查询7[[#This Row],[capex]]/查询7[[#This Row],[revenue]] -> 0.024034571 | I13: =查询7[[#This Row],[net_profit_margin]]-F16 -> 0.0090001499 | J13: =查询7[[#This Row],[free_cash_flow]]/E16-1 -> 0.225362 | K13: =查询7[[#This Row],[free_cash_flow]]/E16-1 -> 0.225362
... A28: AAPL | B28: 42826 | C28: 131247000000 | D28: 6309000000 | E28: 33270000000 | F28: 0.22034789 | G28: 27 | H28: =查询7[[#This Row],[capex]]/查询7[[#This Row],[revenue]] -> 0.04806967 | I28: =查询7[[#This Row],[net_profit_margin]]-F31 -> -0.0080569818 | J28: =查询7[[#This Row],[free_cash_flow]]/E31-1 -> #DIV/0! | K28: =查询7[[#This Row],[free_cash_flow]]/E31-1 -> #DIV/0!
A29: AAPL | B29: 42735 | C29: 78351000000 | D29: 3334000000 | F29: 0.22834425 | G29: 28 | H29: =查询7[[#This Row],[capex]]/查询7[[#This Row],[revenue]] -> 0.042552105 | I29: =查询7[[#This Row],[net_profit_margin]]-F32 -> -0.013655438 | J29: =查询7[[#This Row],[free_cash_flow]]/E32-1 -> #DIV/0! | K29: =查询7[[#This Row],[free_cash_flow]]/E32-1 -> #DIV/0!
A30: AAPL | B30: 42546 | C30: 168787000000 | D30: 8757000000 | F30: 0.21727384 | G30: 29 | H30: =查询7[[#This Row],[capex]]/查询7[[#This Row],[revenue]] -> 0.051881958 | I30: =查询7[[#This Row],[net_profit_margin]]-F33 -> -0.014706137 | J30: =查询7[[#This Row],[free_cash_flow]]/E33-1 -> #DIV/0! | K30: =查询7[[#This Row],[free_cash_flow]]/E33-1 -> #DIV/0!
A31: AAPL | B31: 42455 | C31: 126429000000 | D31: 5948000000 | F31: 0.22840488 | G31: 30 | H31: =查询7[[#This Row],[capex]]/查询7[[#This Row],[revenue]] -> 0.047046168 | I31: =查询7[[#This Row],[net_profit_margin]]-F34 -> -0.0098368728 | J31: =查询7[[#This Row],[free_cash_flow]]/E34-1 -> #DIV/0! | K31: =查询7[[#This Row],[free_cash_flow]]/E34-1 -> #DIV/0!
A32: AAPL | B32: 42364 | C32: 75872000000 | D32: 3612000000 | F32: 0.24199968 | G32: 31 | H32: =查询7[[#This Row],[capex]]/查询7[[#This Row],[revenue]] -> 0.047606495 | I32: =查询7[[#This Row],[net_profit_margin]]-F35 -> 0.00038786582 | J32: =查询7[[#This Row],[free_cash_flow]]/E35-1 -> #DIV/0! | K32: =查询7[[#This Row],[free_cash_flow]]/E35-1 -> #DIV/0!
A33: AAPL | B33: 42182 | C33: 182214000000 | D33: 7629000000 | F33: 0.23197998 | G33: 32 | H33: =查询7[[#This Row],[capex]]/查询7[[#This Row],[revenue]] -> 0.041868353 | I33: =查询7[[#This Row],[net_profit_margin]]-F36 -> 0.011303512 | J33: =查询7[[#This Row],[free_cash_flow]]/E36-1 -> #DIV/0! | K33: =查询7[[#This Row],[free_cash_flow]]/E36-1 -> #DIV/0!
A34: AAPL | B34: 42091 | C34: 132609000000 | D34: 5586000000 | F34: 0.23824175 | G34: 33 | H34: =查询7[[#This Row],[capex]]/查询7[[#This Row],[revenue]] -> 0.042123838 | I34: =查询7[[#This Row],[net_profit_margin]]-F37 -> 0.012602461 | J34: =查询7[[#This Row],[free_cash_flow]]/E37-1 -> #DIV/0! | K34: =查询7[[#This Row],[free_cash_flow]]/E37-1 -> #DIV/0!
A35: AAPL | B35: 42000 | C35: 74599000000 | D35: 3217000000 | F35: 0.24161182 | G35: 34 | H35: =查询7[[#This Row],[capex]]/查询7[[#This Row],[revenue]] -> 0.043123902 | I35: =查询7[[#This Row],[net_profit_margin]]-F38 -> 0.014643731 | J35: =查询7[[#This Row],[free_cash_flow]]/E38-1 -> -1 | K35: =查询7[[#This Row],[free_cash_flow]]/E38-1 -> -1
A36: AAPL | B36: 41818 | C36: 140672000000 | D36: 5745000000 | F36: 0.22067647 | G36: 35 | H36: =查询7[[#This Row],[capex]]/查询7[[#This Row],[revenue]] -> 0.040839684 | I36: =查询7[[#This Row],[net_profit_margin]]-F39 -> -0.00058734067 | J36: =查询7[[#This Row],[free_cash_flow]]/E39-1 -> -1 | K36: =查询7[[#This Row],[free_cash_flow]]/E39-1 -> -1
A37: AAPL | B37: 41727 | C37: 103240000000 | D37: 3367000000 | F37: 0.22563929 | G37: 36 | H37: =查询7[[#This Row],[capex]]/查询7[[#This Row],[revenue]] -> 0.032613328 | I37: =查询7[[#This Row],[net_profit_margin]]-F40 -> -0.0049574616 | J37: =查询7[[#This Row],[free_cash_flow]]/E40-1 -> -1 | K37: =查询7[[#This Row],[free_cash_flow]]/E40-1 -> -1
A38: AAPL | B38: 41636 | C38: 57594000000 | D38: 1985000000 | E38: 20685000000 | F38: 0.22696809 | G38: 37 | H38: =查询7[[#This Row],[capex]]/查询7[[#This Row],[revenue]] -> 0.034465396 | I38: =查询7[[#This Row],[net_profit_margin]]-F41 -> -0.012942391 | J38: =查询7[[#This Row],[free_cash_flow]]/E41-1 -> -0.020086219 | K38: =查询7[[#This Row],[free_cash_flow]]/E41-1 -> -0.020086219
A39: AAPL | B39: 41454 | C39: 133438000000 | D39: 6210000000 | E39: 37548000000 | F39: 0.22126381 | G39: 38 | H39: =查询7[[#This Row],[capex]]/查询7[[#This Row],[revenue]] -> 0.046538467 | I39: =查询7[[#This Row],[net_profit_margin]]-F42 -> -0.056730584 | J39: =查询7[[#This Row],[free_cash_flow]]/E42-1 -> 0.017947189 | K39: =查询7[[#This Row],[free_cash_flow]]/E42-1 -> 0.017947189
A40: AAPL | B40: 41363 | C40: 98115000000 | D40: 4325000000 | E40: 31605000000 | F40: 0.23059675 | G40: 39 | H40: =查询7[[#This Row],[capex]]/查询7[[#This Row],[revenue]] -> 0.044080925 | I40: =查询7[[#This Row],[net_profit_margin]]-F43 -> -0.058064251 | J40: =查询7[[#This Row],[free_cash_flow]]/E43-1 -> 0.09918965 | K40: =查询7[[#This Row],[free_cash_flow]]/E43-1 -> 0.09918965
A41: AAPL | B41: 41272 | C41: 54512000000 | D41: 2317000000 | E41: 21109000000 | F41: 0.23991048 | G41: 40 | H41: =查询7[[#This Row],[capex]]/查询7[[#This Row],[revenue]] -> 0.042504403 | I41: =查询7[[#This Row],[net_profit_margin]]-F44 -> -0.042048385 | J41: =查询7[[#This Row],[free_cash_flow]]/E44-1 -> 0.30037578 | K41: =查询7[[#This Row],[free_cash_flow]]/E44-1 -> 0.30037578
A42: AAPL | B42: 41090 | C42: 120542000000 | D42: 4834000000 | E42: 36886000000 | F42: 0.27799439 | G42: 41 | H42: =查询7[[#This Row],[capex]]/查询7[[#This Row],[revenue]] -> 0.040102205 | I42: =查询7[[#This Row],[net_profit_margin]]-F45 -> 0.036693551 | J42: =查询7[[#This Row],[free_cash_flow]]/E45-1 -> 0.50647335 | K42: =查询7[[#This Row],[free_cash_flow]]/E45-1 -> 0.50647335
A43: AAPL | B43: 40999 | C43: 85519000000 | D43: 2778000000 | E43: 28753000000 | F43: 0.288661 | G43: 42 | H43: =查询7[[#This Row],[capex]]/查询7[[#This Row],[revenue]] -> 0.032484009 | I43: =查询7[[#This Row],[net_profit_margin]]-F46 -> 0.055409365 | J43: =查询7[[#This Row],[free_cash_flow]]/E46-1 -> 1.0314399 | K43: =查询7[[#This Row],[free_cash_flow]]/E46-1 -> 1.0314399
A44: AAPL | B44: 40908 | C44: 46333000000 | D44: 1321000000 | E44: 16233000000 | F44: 0.28195886 | G44: 43 | H44: =查询7[[#This Row],[capex]]/查询7[[#This Row],[revenue]] -> 0.028510996 | I44: =查询7[[#This Row],[net_profit_margin]]-F47 -> 0.057434724 | J44: =查询7[[#This Row],[free_cash_flow]]/E47-1 -> 0.89660007 | K44: =查询7[[#This Row],[free_cash_flow]]/E47-1 -> 0.89660007
A45: AAPL | B45: 40719 | C45: 79979000000 | D45: 2615000000 | E45: 24485000000 | F45: 0.24130084 | G45: 44 | H45: =查询7[[#This Row],[capex]]/查询7[[#This Row],[revenue]] -> 0.032696083 | I45: =查询7[[#This Row],[net_profit_margin]]-F48 -> 0.025067162 | J45: =查询7[[#This Row],[free_cash_flow]]/E48-1 -> 1.0986543 | K45: =查询7[[#This Row],[free_cash_flow]]/E48-1 -> 1.0986543
A46: AAPL | B46: 40628 | C46: 51408000000 | D46: 1838000000 | E46: 14154000000 | F46: 0.23325163 | G46: 45 | H46: =查询7[[#This Row],[capex]]/查询7[[#This Row],[revenue]] -> 0.03575319 | I46: =查询7[[#This Row],[net_profit_margin]]-F49 -> 0.012156438 | J46: =查询7[[#This Row],[free_cash_flow]]/E49-1 -> 0.89706474 | K46: =查询7[[#This Row],[free_cash_flow]]/E49-1 -> 0.89706474
A47: AAPL | B47: 40537 | C47: 26741000000 | D47: 1214000000 | E47: 8559000000 | F47: 0.22452414 | G47: 46 | H47: =查询7[[#This Row],[capex]]/查询7[[#This Row],[revenue]] -> 0.045398452 | I47: =查询7[[#This Row],[net_profit_margin]]-F50 -> 0.1123618 | J47: =查询7[[#This Row],[free_cash_flow]]/E50-1 -> -2.1818558 | K47: =查询7[[#This Row],[free_cash_flow]]/E50-1 -> -2.1818558
A48: AAPL | B48: 40355 | C48: 44882000000 | D48: 1245000000 | E48: 11667000000 | F48: 0.21623368 | G48: 47 | H48: =查询7[[#This Row],[capex]]/查询7[[#This Row],[revenue]] -> 0.027739406 | I48: =查询7[[#This Row],[net_profit_margin]]-F51 -> 0.1070983 | J48: =查询7[[#This Row],[free_cash_flow]]/E51-1 -> -2.5207247 | K48: =查询7[[#This Row],[free_cash_flow]]/E51-1 -> -2.5207247
A49: AAPL | B49: 40264 | C49: 29182000000 | D49: 650000000 | E49: 7461000000 | F49: 0.2210952 | G49: 48 | H49: =查询7[[#This Row],[capex]]/查询7[[#This Row],[revenue]] -> 0.022274005 | I49: =查询7[[#This Row],[net_profit_margin]]-F52 -> 0.11107188 | J49: =查询7[[#This Row],[free_cash_flow]]/E52-1 -> -1.9321589 | K49: =查询7[[#This Row],[free_cash_flow]]/E52-1 -> -1.9321589
... A70: AMZN | B70: 43373 | C70: 160504000000 | D70: 9693000000 | E70: 4553000000 | F70: 0.043899217 | G70: 21 | H70: =查询7[[#This Row],[capex]]/查询7[[#This Row],[revenue]] -> 0.060391018 | I70: =查询7[[#This Row],[net_profit_margin]]-F73 -> 0.033883291 | J70: =查询7[[#This Row],[free_cash_flow]]/E73-1 -> #DIV/0! | K70: =查询7[[#This Row],[free_cash_flow]]/E73-1 -> #DIV/0!
A71: AMZN | B71: 43281 | C71: 103928000000 | F71: 0.040056578 | G71: 22 | H71: =查询7[[#This Row],[capex]]/查询7[[#This Row],[revenue]] -> 0 | I71: =查询7[[#This Row],[net_profit_margin]]-F74 -> 0.027554711 | J71: =查询7[[#This Row],[free_cash_flow]]/E74-1 -> #DIV/0! | K71: =查询7[[#This Row],[free_cash_flow]]/E74-1 -> #DIV/0!
A72: AMZN | B72: 43190 | C72: 51042000000 | F72: 0.031914894 | G72: 23 | H72: =查询7[[#This Row],[capex]]/查询7[[#This Row],[revenue]] -> 0 | I72: =查询7[[#This Row],[net_profit_margin]]-F75 -> 0.011642731 | J72: =查询7[[#This Row],[free_cash_flow]]/E75-1 -> -1 | K72: =查询7[[#This Row],[free_cash_flow]]/E75-1 -> -1
A73: AMZN | B73: 43008 | C73: 117413000000 | F73: 0.010015927 | G73: 24 | H73: =查询7[[#This Row],[capex]]/查询7[[#This Row],[revenue]] -> 0 | I73: =查询7[[#This Row],[net_profit_margin]]-F76 -> -0.0075674916 | J73: =查询7[[#This Row],[free_cash_flow]]/E76-1 -> -1 | K73: =查询7[[#This Row],[free_cash_flow]]/E76-1 -> -1
A74: AMZN | B74: 42916 | C74: 73669000000 | F74: 0.012501866 | G74: 25 | H74: =查询7[[#This Row],[capex]]/查询7[[#This Row],[revenue]] -> 0 | I74: =查询7[[#This Row],[net_profit_margin]]-F77 -> -0.010510967 | J74: =查询7[[#This Row],[free_cash_flow]]/E77-1 -> -1 | K74: =查询7[[#This Row],[free_cash_flow]]/E77-1 -> -1
...

Sheet pq_fh_earnings
A1: symbol | B1: period | C1: actual_eps | D1: estimate_eps | E1: surprise_pct | F1: rank | J1: symbol | K1: period | L1: actual_eps | M1: estimate_eps | N1: surprise_pct | O1: rank
A2: AAPL | B2: 46022 | C2: 2.84 | D2: 2.7257 | E2: 4.1934 | F2: 1 | J2: AAPL | K2: 46022 | L2: 2.84 | M2: 2.7257 | N2: 4.1934 | O2: 1
A3: AAPL | B3: 45930 | C3: 1.85 | D3: 1.8075 | E3: 2.3513 | F3: 2 | J3: AAPL | K3: 45930 | L3: 1.85 | M3: 1.8075 | N3: 2.3513 | O3: 2
A4: AAPL | B4: 45838 | C4: 1.57 | D4: 1.4626 | E4: 7.3431 | F4: 3 | J4: AAPL | K4: 45838 | L4: 1.57 | M4: 1.4626 | N4: 7.3431 | O4: 3
A5: AAPL | B5: 45747 | C5: 1.65 | D5: 1.6596 | E5: -0.5785 | F5: 4 | J5: AAPL | K5: 45747 | L5: 1.65 | M5: 1.6596 | N5: -0.5785 | O5: 4
A6: AMZN | B6: 46022 | C6: 1.95 | D6: 2.011 | E6: -3.0333 | F6: 1 | J6: AMZN | K6: 46022 | L6: 1.95 | M6: 2.011 | N6: -3.0333 | O6: 1
A7: AMZN | B7: 45930 | C7: 1.95 | D7: 1.605 | E7: 21.4953 | F7: 2 | J7: AMZN | K7: 45930 | L7: 1.95 | M7: 1.605 | N7: 21.4953 | O7: 2
A8: AMZN | B8: 45838 | C8: 1.68 | D8: 1.3545 | E8: 24.031 | F8: 3 | J8: AMZN | K8: 45838 | L8: 1.68 | M8: 1.3545 | N8: 24.031 | O8: 3
A9: AMZN | B9: 45747 | C9: 1.59 | D9: 1.3893 | E9: 14.4461 | F9: 4 | J9: AMZN | K9: 45747 | L9: 1.59 | M9: 1.3893 | N9: 14.4461 | O9: 4
A10: GOOGL | B10: 46022 | C10: 2.82 | D10: 2.7063 | E10: 4.2013 | F10: 1 | J10: GOOGL | K10: 46022 | L10: 2.82 | M10: 2.7063 | N10: 4.2013 | O10: 1
A11: GOOGL | B11: 45930 | C11: 3.1 | D11: 2.3954 | E11: 29.4147 | F11: 2 | J11: GOOGL | K11: 45930 | L11: 3.1 | M11: 2.3954 | N11: 29.4147 | O11: 2
A12: GOOGL | B12: 45838 | C12: 2.31 | D12: 2.25 | E12: 2.6667 | F12: 3 | J12: GOOGL | K12: 45838 | L12: 2.31 | M12: 2.25 | N12: 2.6667 | O12: 3
A13: GOOGL | B13: 45747 | C13: 2.27 | D13: 2.0726 | E13: 9.5243 | F13: 4 | J13: GOOGL | K13: 45747 | L13: 2.27 | M13: 2.0726 | N13: 9.5243 | O13: 4
... A29: TSLA | B29: 45747 | C29: 0.27 | D29: 0.399 | E29: -32.3308 | F29: 4 | J29: TSLA | K29: 45747 | L29: 0.27 | M29: 0.399 | N29: -32.3308 | O29: 4

Sheet fh_earn_TSLA
A1: symbol | B1: period | C1: actual_eps | D1: estimate_eps | E1: surprise_pct
A2: TSLA | B2: 2025-12-31 | C2: 0.5 | D2: 0.4559 | E2: 9.6732
A3: TSLA | B3: 2025-09-30 | C3: 0.5 | D3: 0.5586 | E3: -10.4905
A4: TSLA | B4: 2025-06-30 | C4: 0.4 | D4: 0.4373 | E4: -8.5296
A5: TSLA | B5: 2025-03-31 | C5: 0.27 | D5: 0.399 | E5: -32.3308

Sheet fh_earn_META
A1: symbol | B1: period | C1: actual_eps | D1: estimate_eps | E1: surprise_pct
A2: META | B2: 2025-12-31 | C2: 8.88 | D2: 8.3992 | E2: 5.7244
A3: META | B3: 2025-09-30 | C3: 7.25 | D3: 6.8245 | E3: 6.2349
A4: META | B4: 2025-06-30 | C4: 7.14 | D4: 6.0352 | E4: 18.3059
A5: META | B5: 2025-03-31 | C5: 6.43 | D5: 5.3859 | E5: 19.3858

Sheet fh_earn_AMZN
A1: symbol | B1: period | C1: actual_eps | D1: estimate_eps | E1: surprise_pct
A2: AMZN | B2: 2025-12-31 | C2: 1.95 | D2: 2.011 | E2: -3.0333
A3: AMZN | B3: 2025-09-30 | C3: 1.95 | D3: 1.605 | E3: 21.4953
A4: AMZN | B4: 2025-06-30 | C4: 1.68 | D4: 1.3545 | E4: 24.031
A5: AMZN | B5: 2025-03-31 | C5: 1.59 | D5: 1.3893 | E5: 14.4461

Sheet fh_earn_GOOGL
A1: symbol | B1: period | C1: actual_eps | D1: estimate_eps | E1: surprise_pct
A2: GOOGL | B2: 2025-12-31 | C2: 2.82 | D2: 2.7063 | E2: 4.2013
A3: GOOGL | B3: 2025-09-30 | C3: 3.1 | D3: 2.3954 | E3: 29.4147
A4: GOOGL | B4: 2025-06-30 | C4: 2.31 | D4: 2.25 | E4: 2.6667
A5: GOOGL | B5: 2025-03-31 | C5: 2.27 | D5: 2.0726 | E5: 9.5243

Sheet fh_earn_MSFT
A1: symbol | B1: period | C1: actual_eps | D1: estimate_eps | E1: surprise_pct
A2: MSFT | B2: 2025-12-31 | C2: 4.14 | D2: 4.0345 | E2: 2.6149
A3: MSFT | B3: 2025-09-30 | C3: 4.13 | D3: 3.7391 | E3: 10.4544
A4: MSFT | B4: 2025-06-30 | C4: 3.65 | D4: 3.4368 | E4: 6.2034
A5: MSFT | B5: 2025-03-31 | C5: 3.46 | D5: 3.2846 | E5: 5.3401

Sheet fh_earn_AAPL
A1: symbol | B1: period | C1: actual_eps | D1: estimate_eps | E1: surprise_pct
A2: AAPL | B2: 2025-12-31 | C2: 2.84 | D2: 2.7257 | E2: 4.1934
A3: AAPL | B3: 2025-09-30 | C3: 1.85 | D3: 1.8075 | E3: 2.3513
A4: AAPL | B4: 2025-06-30 | C4: 1.57 | D4: 1.4626 | E4: 7.3431
A5: AAPL | B5: 2025-03-31 | C5: 1.65 | D5: 1.6596 | E5: -0.5785

Sheet fh_fin_TSLA
A1: symbol | B1: period | C1: revenue | D1: capex | E1: free_cash_flow | F1: net_profit_margin
A2: TSLA | B2: 2025-09-30 00:00:00 | C2: 69926000000 | D2: 6134000000 | E2: 4800000000 | F2: 0.042244659
A3: TSLA | B3: 2025-06-30 00:00:00 | C3: 41831000000 | D3: 3886000000 | E3: 810000000 | F3: 0.037794937
A4: TSLA | B4: 2025-03-31 00:00:00 | C4: 19335000000 | D4: 1492000000 | E4: 664000000 | F4: 0.021153349
A5: TSLA | B5: 2024-09-30 00:00:00 | C5: 71983000000 | D5: 8556000000 | E5: 1553000000 | F5: 0.066321215
A6: TSLA | B6: 2024-06-30 00:00:00 | C6: 46801000000 | D6: 5043000000 | E6: -1189000000 | F6: 0.055703938
A7: TSLA | B7: 2024-03-31 00:00:00 | C7: 21301000000 | D7: 2773000000 | E7: -2531000000 | F7: 0.053002206
A8: TSLA | B8: 2023-09-30 00:00:00 | C8: 71606000000 | D8: 6592000000 | E8: 2294000000 | F8: 0.098720778
A9: TSLA | B9: 2023-06-30 00:00:00 | C9: 48256000000 | D9: 4132000000 | E9: 1446000000 | F9: 0.10809019
A10: TSLA | B10: 2023-03-31 00:00:00 | C10: 23329000000 | D10: 2072000000 | E10: 441000000 | F10: 0.10772001
A11: TSLA | B11: 2022-09-30 00:00:00 | C11: 57144000000 | D11: 5300000000 | E11: 6146000000 | F11: 0.1552044
A12: TSLA | B12: 2022-06-30 00:00:00 | C12: 35690000000 | D12: 3497000000 | E12: 2849000000 | F12: 0.15626226
A13: TSLA | B13: 2022-03-31 00:00:00 | C13: 18756000000 | D13: 1767000000 | E13: 2228000000 | F13: 0.17690339
... A24: TSLA | B24: 2018-06-30 00:00:00 | C24: 7410982000 | D24: 1265475000 | E24: -1793515000 | F24: -0.19256422
A25: TSLA | B25: 2018-03-31 00:00:00 | C25: 3408751000 | D25: 655662000 | F25: -0.20815571
A26: TSLA | B26: 2017-09-30 00:00:00 | C26: 8470502000 | D26: 2628126000 | F26: -0.15182689
A27: TSLA | B27: 2017-06-30 00:00:00 | C27: 5485827000 | D27: 1511692000 | F27: -0.12152662
A28: TSLA | B28: 2017-03-31 00:00:00 | C28: 2696270000 | D28: 552624000 | F28: -0.12249404
A29: TSLA | B29: 2016-09-30 00:00:00 | C29: 4715501000 | D29: 759190000 | F29: -0.11739516
A30: TSLA | B30: 2016-06-30 00:00:00 | C30: 2417065000 | D30: 511579000 | F30: -0.23808007
A31: TSLA | B31: 2016-03-31 00:00:00 | C31: 1147048000 | D31: 216859000 | F31: -0.24608125
A32: TSLA | B32: 2015-09-30 00:00:00 | C32: 2831645000 | D32: 1223628000 | F32: -0.20068405
A33: TSLA | B33: 2015-06-30 00:00:00 | C33: 1894856000 | D33: 831225000 | F33: -0.17859299
A34: TSLA | B34: 2015-03-31 00:00:00 | C34: 939880000 | D34: 426060000 | F34: -0.16404328
A35: TSLA | B35: 2014-09-30 00:00:00 | C35: 2241695000 | D35: 601224000 | F35: -0.083156272
A36: TSLA | B36: 2014-06-30 00:00:00 | C36: 1389891000 | D36: 317049000 | F36: -0.080367453
A37: TSLA | B37: 2014-03-31 00:00:00 | C37: 620542000 | D37: 141364000 | E37: -80724000 | F37: -0.080252424
A38: TSLA | B38: 2013-09-30 00:00:00 | C38: 1398277000 | D38: 174790000 | E38: -46558000 | F38: -0.04130083
A39: TSLA | B39: 2013-06-30 00:00:00 | C39: 966931000 | D39: 98242000 | E39: -72356000 | F39: -0.019912486
A40: TSLA | B40: 2013-03-31 00:00:00 | C40: 561792000 | D40: 57727000 | E40: 6352000 | F40: 0.020021645
A41: TSLA | B41: 2012-09-30 00:00:00 | C41: 106924000 | D41: 197745000 | E41: -403765000 | F41: -2.8644832
A42: TSLA | B42: 2012-06-30 00:00:00 | C42: 56820000 | D42: 129273000 | E42: -240341000 | F42: -3.4402675
A43: TSLA | B43: 2012-03-31 00:00:00 | C43: 30167000 | D43: 67987000 | E43: -118074000 | F43: -2.9791826
A44: TSLA | B44: 2011-09-30 00:00:00 | C44: 164867000 | D44: 143634000 | E44: -230910000 | F44: -1.0488576
A45: TSLA | B45: 2011-06-30 00:00:00 | C45: 107201000 | D45: 74790000 | E45: -140575000 | F45: -1.0059981

Sheet fh_fin_META
A1: symbol | B1: period | C1: revenue | D1: capex | E1: free_cash_flow | F1: net_profit_margin
A2: META | B2: 2025-09-30 00:00:00 | C2: 141073000000 | D2: 48308000000 | E2: 31278000000 | F2: 0.26716664
A3: META | B3: 2025-06-30 00:00:00 | C3: 89830000000 | D3: 29479000000 | E3: 20108000000 | F3: 0.38941334
A4: META | B4: 2025-03-31 00:00:00 | C4: 42314000000 | D4: 12941000000 | E4: 11085000000 | F4: 0.39334499
A5: META | B5: 2024-09-30 00:00:00 | C5: 116116000000 | D5: 22831000000 | E5: 40509000000 | F5: 0.35759069
A6: META | B6: 2024-06-30 00:00:00 | C6: 75527000000 | D6: 14573000000 | E6: 24043000000 | F6: 0.34204986
A7: META | B7: 2024-03-31 00:00:00 | C7: 36455000000 | D7: 6400000000 | E7: 12846000000 | F7: 0.33929502
A8: META | B8: 2023-09-30 00:00:00 | C8: 94791000000 | D8: 19601000000 | E8: 32108000000 | F8: 0.26459263
A9: META | B9: 2023-06-30 00:00:00 | C9: 60645000000 | D9: 13058000000 | E9: 18249000000 | F9: 0.222574
A10: META | B10: 2023-03-31 00:00:00 | C10: 28645000000 | D10: 6842000000 | E10: 7156000000 | F10: 0.1993018
A11: META | B11: 2022-09-30 00:00:00 | C11: 84444000000 | D11: 22388000000 | E11: 13576000000 | F11: 0.21963668
A12: META | B12: 2022-06-30 00:00:00 | C12: 56729000000 | D12: 13013000000 | E12: 13259000000 | F12: 0.24946676
A13: META | B13: 2022-03-31 00:00:00 | C13: 27908000000 | D13: 5441000000 | E13: 8635000000 | F13: 0.26748603
... A42: META | B42: 2012-06-30 00:00:00 | C42: 2242000000 | D42: 866000000 | E42: -183000000 | F42: 0.021409456

Sheet fh_fin_AMZN
A1: symbol | B1: period | C1: revenue | D1: capex | E1: free_cash_flow | F1: net_profit_margin
A2: AMZN | B2: 2025-09-30 00:00:00 | C2: 503538000000 | D2: 92297000000 | E2: -7242000000 | F2: 0.11216234
A3: AMZN | B3: 2025-06-30 00:00:00 | C3: 323369000000 | D3: 57202000000 | E3: -7672000000 | F3: 0.10913538
A4: AMZN | B4: 2025-03-31 00:00:00 | C4: 155667000000 | D4: 25019000000 | E4: -8004000000 | F4: 0.11002332
A5: AMZN | B5: 2024-06-30 00:00:00 | C5: 291290000000 | D5: 32545000000 | E5: 11725000000 | F5: 0.082103745
A6: AMZN | B6: 2024-03-31 00:00:00 | C6: 143313000000 | D6: 14925000000 | E6: 4064000000 | F6: 0.072784744
A7: AMZN | B7: 2023-09-30 00:00:00 | C7: 404824000000 | D7: 38141000000 | E7: 4340000000 | F7: 0.048912614
A8: AMZN | B8: 2023-06-30 00:00:00 | C8: 261741000000 | D8: 25662000000 | E8: -4398000000 | F8: 0.037907703
A9: AMZN | B9: 2023-03-31 00:00:00 | C9: 127358000000 | D9: 14207000000 | E9: -9419000000 | F9: 0.02490617
A10: AMZN | B10: 2022-09-30 00:00:00 | C10: 364779000000 | D10: 47053000000 | E10: -29474000000 | F10: -0.0082241576
A11: AMZN | B11: 2022-06-30 00:00:00 | C11: 237678000000 | D11: 30675000000 | E11: -24500000000 | F11: -0.024705694
A12: AMZN | B12: 2022-03-31 00:00:00 | C12: 116444000000 | D12: 14951000000 | E12: -17741000000 | F12: -0.033011576
A13: AMZN | B13: 2021-09-30 00:00:00 | C13: 332410000000 | D13: 42118000000 | E13: -17877000000 | F13: 0.05728167
... A22: AMZN | B22: 2018-09-30 00:00:00 | C22: 160504000000 | D22: 9693000000 | E22: 4553000000 | F22: 0.043899217
A23: AMZN | B23: 2018-06-30 00:00:00 | C23: 103928000000 | F23: 0.040056578
A24: AMZN | B24: 2018-03-31 00:00:00 | C24: 51042000000 | F24: 0.031914894
A25: AMZN | B25: 2017-09-30 00:00:00 | C25: 117413000000 | F25: 0.010015927
A26: AMZN | B26: 2017-06-30 00:00:00 | C26: 73669000000 | F26: 0.012501866
A27: AMZN | B27: 2017-03-31 00:00:00 | C27: 35714000000 | D27: 1861000000 | E27: -3451000000 | F27: 0.020272162
A28: AMZN | B28: 2016-09-30 00:00:00 | C28: 92246000000 | D28: 4731000000 | E28: 1060000000 | F28: 0.017583418
A29: AMZN | B29: 2016-06-30 00:00:00 | C29: 59532000000 | D29: 2890000000 | E29: -1585000000 | F29: 0.023012833
A30: AMZN | B30: 2016-03-31 00:00:00 | C30: 29128000000 | D30: 1179000000 | E30: -3339000000 | F30: 0.01761192
A31: AMZN | B31: 2015-09-30 00:00:00 | C31: 71259000000 | D31: 3280000000 | E31: -172000000 | F31: 0.0015997979
A32: AMZN | B32: 2015-06-30 00:00:00 | C32: 45901000000 | D32: 2084000000 | E32: -1586000000 | F32: 0.00076251062
A33: AMZN | B33: 2015-03-31 00:00:00 | C33: 22717000000 | D33: 871000000 | E33: -2370000000 | F33: -0.0025091341
A34: AMZN | B34: 2014-09-30 00:00:00 | C34: 59659000000 | D34: 3748000000 | E34: -3621000000 | F34: -0.0076266783
A35: AMZN | B35: 2014-06-30 00:00:00 | C35: 39081000000 | D35: 2370000000 | E35: -4010000000 | F35: -0.00046058187
A36: AMZN | B36: 2014-03-31 00:00:00 | C36: 19741000000 | D36: 1080000000 | E36: -3582000000 | F36: 0.0054708475
A37: AMZN | B37: 2013-09-30 00:00:00 | C37: 48865000000 | D37: 2565000000 | E37: -2668000000 | F37: 0.00069579454
A38: AMZN | B38: 2013-06-30 00:00:00 | C38: 31774000000 | D38: 1526000000 | E38: -3018000000 | F38: 0.0023604205
A39: AMZN | B39: 2013-03-31 00:00:00 | C39: 16070000000 | D39: 670000000 | E39: -3042000000 | F39: 0.0051026758
A40: AMZN | B40: 2012-09-30 00:00:00
A41: AMZN | B41: 2012-06-30 00:00:00
A42: AMZN | B42: 2012-03-31 00:00:00
A43: AMZN | B43: 2011-09-30 00:00:00
A44: AMZN | B44: 2011-06-30 00:00:00
A45: AMZN | B45: 2011-03-31 00:00:00 | C45: 9857000000 | D45: 298000000 | E45: -1884000000 | F45: 0.0203916
A46: AMZN | B46: 2010-09-30 00:00:00 | C46: 21257000000 | D46: 651000000 | E46: -644000000 | F46: 0.034623889
A47: AMZN | B47: 2010-06-30 00:00:00 | C47: 13697000000 | D47: 336000000 | E47: -1184000000 | F47: 0.036869387
A48: AMZN | B48: 2010-03-31 00:00:00 | C48: 7131000000 | D48: 140000000 | E48: -1238000000 | F48: 0.041929603

Sheet fh_fin_GOOGL
A1: symbol | B1: period | C1: revenue | D1: capex | E1: free_cash_flow | F1: net_profit_margin
A2: GOOGL | B2: 2025-09-30 00:00:00 | C2: 289007000000 | D2: 63596000000 | E2: 48715000000 | F2: 0.338106
A3: GOOGL | B3: 2025-06-30 00:00:00 | C3: 186662000000 | D3: 39643000000 | E3: 24254000000 | F3: 0.33609412
A4: GOOGL | B4: 2025-03-31 00:00:00 | C4: 90234000000 | D4: 17197000000 | E4: 18953000000 | F4: 0.38278254
A5: GOOGL | B5: 2024-09-30 00:00:00 | C5: 253549000000 | D5: 38259000000 | E5: 47927000000 | F5: 0.2902082
A6: GOOGL | B6: 2024-06-30 00:00:00 | C6: 165281000000 | D6: 25198000000 | E6: 30290000000 | F6: 0.28606434
A7: GOOGL | B7: 2024-03-31 00:00:00 | C7: 80539000000 | D7: 12012000000 | E7: 16836000000 | F7: 0.29379555
A8: GOOGL | B8: 2023-09-30 00:00:00 | C8: 221084000000 | D8: 21232000000 | E8: 61599000000 | F8: 0.24021639
A9: GOOGL | B9: 2023-06-30 00:00:00 | C9: 144391000000 | D9: 13177000000 | E9: 38998000000 | F9: 0.23144794
A10: GOOGL | B10: 2023-03-31 00:00:00 | C10: 69787000000 | D10: 6289000000 | E10: 17220000000 | F10: 0.21567054
A11: GOOGL | B11: 2022-09-30 00:00:00 | C11: 206788000000 | D11: 23890000000 | E11: 43991000000 | F11: 0.22413293
A12: GOOGL | B12: 2022-06-30 00:00:00 | C12: 137696000000 | D12: 16614000000 | E12: 27914000000 | F12: 0.23557692
A13: GOOGL | B13: 2022-03-31 00:00:00 | C13: 68011000000 | D13: 9786000000 | E13: 15320000000 | F13: 0.24166679
... A32: GOOGL | B32: 2015-09-30 00:00:00 | C32: 53660000000 | D32: 7815000000 | E32: 11794000000 | F32: 0.21291465

Sheet fh_fin_MSFT
A1: symbol | B1: period | C1: revenue | D1: capex | E1: free_cash_flow | F1: net_profit_margin
A2: MSFT | B2: 2025-12-31 00:00:00 | C2: 158946000000 | D2: 49270000000 | E2: 31545000000 | F2: 0.41652511
A3: MSFT | B3: 2025-09-30 00:00:00 | C3: 77673000000 | D3: 19394000000 | E3: 25663000000 | F3: 0.35722838
A4: MSFT | B4: 2025-03-31 00:00:00 | C4: 205283000000 | D4: 47472000000 | E4: 46043000000 | F4: 0.3633959
A5: MSFT | B5: 2024-12-31 00:00:00 | C5: 135217000000 | D5: 30727000000 | E5: 25744000000 | F5: 0.36071648
A6: MSFT | B6: 2024-09-30 00:00:00 | C6: 65585000000 | D6: 14923000000 | E6: 19257000000 | F6: 0.37610734
A7: MSFT | B7: 2023-09-30 00:00:00 | C7: 56517000000 | D7: 9917000000 | E7: 20666000000 | F7: 0.3944123
A8: MSFT | B8: 2023-03-31 00:00:00 | C8: 155726000000 | D8: 19164000000 | E8: 39648000000 | F8: 0.33571786
A9: MSFT | B9: 2022-12-31 00:00:00 | C9: 102869000000 | D9: 12557000000 | E9: 21814000000 | F9: 0.33033275
A10: MSFT | B10: 2022-09-30 00:00:00 | C10: 50122000000 | D10: 6283000000 | E10: 16915000000 | F10: 0.35026535
A11: MSFT | B11: 2022-03-31 00:00:00 | C11: 146405000000 | D11: 17015000000 | E11: 47391000000 | F11: 0.38248694
A12: MSFT | B12: 2021-12-31 00:00:00 | C12: 97045000000 | D12: 11675000000 | E12: 27345000000 | F12: 0.40465763
A13: MSFT | B13: 2021-09-30 00:00:00 | C13: 45317000000 | D13: 5810000000 | E13: 18730000000 | F13: 0.4524792
... A24: MSFT | B24: 2017-12-31 00:00:00 | C24: 53456000000 | D24: 4718000000 | E24: 15597000000 | F24: 0.0051257109
A25: MSFT | B25: 2017-09-30 00:00:00 | C25: 24538000000 | D25: 2132000000 | F25: 0.2679925
A26: MSFT | B26: 2017-03-31 00:00:00 | C26: 66633000000 | D26: 5846000000 | F26: 0.22047634
A27: MSFT | B27: 2016-12-31 00:00:00 | C27: 44543000000 | D27: 4151000000 | F27: 0.22203264
A28: MSFT | B28: 2016-09-30 00:00:00 | C28: 20453000000 | D28: 2163000000 | F28: 0.22930621
A29: MSFT | B29: 2016-03-31 00:00:00 | C29: 64706000000 | D29: 5688000000 | F29: 0.21135598
A30: MSFT | B30: 2015-12-31 00:00:00 | C30: 44175000000 | D30: 3380000000 | F30: 0.21772496
A31: MSFT | B31: 2015-09-30 00:00:00 | C31: 20379000000 | D31: 1356000000 | F31: 0.22670396
A32: MSFT | B32: 2015-03-31 00:00:00 | C32: 71400000000 | D32: 4163000000 | F32: 0.21551821
A33: MSFT | B33: 2014-12-31 00:00:00 | C33: 49671000000 | D33: 2772000000 | F33: 0.2094381
A34: MSFT | B34: 2014-09-30 00:00:00 | C34: 23201000000 | D34: 1282000000 | F34: 0.19568122
A35: MSFT | B35: 2014-03-31 00:00:00 | C35: 63451000000 | D35: 4155000000 | F35: 0.27520449
A36: MSFT | B36: 2013-12-31 00:00:00 | C36: 43048000000 | D36: 2963000000 | F36: 0.27415908
A37: MSFT | B37: 2013-09-30 00:00:00 | C37: 18529000000 | D37: 1231000000 | F37: 0.28301581
A38: MSFT | B38: 2013-03-31 00:00:00 | C38: 57953000000 | D38: 2463000000 | E38: 20467000000 | F38: 0.29158111
A39: MSFT | B39: 2012-12-31 00:00:00 | C39: 37464000000 | D39: 1533000000 | E39: 11731000000 | F39: 0.28942451
A40: MSFT | B40: 2012-09-30 00:00:00 | C40: 16008000000 | D40: 603000000 | E40: 7881000000 | F40: 0.27898551
A41: MSFT | B41: 2012-03-31 00:00:00 | C41: 55664000000 | D41: 1683000000 | E41: 22266000000 | F41: 0.31384737
A42: MSFT | B42: 2011-09-30 00:00:00 | C42: 17372000000 | D42: 436000000 | E42: 8057000000 | F42: 0.33030163
A43: MSFT | B43: 2011-03-31 00:00:00 | C43: 52576000000 | D43: 1713000000 | E43: 19339000000 | F43: 0.32859099
A44: MSFT | B44: 2010-12-31 00:00:00 | C44: 36148000000 | D44: 1055000000 | E44: 11325000000 | F44: 0.33318579
A45: MSFT | B45: 2010-09-30 00:00:00 | C45: 16195000000 | D45: 564000000 | E45: 7630000000 | F45: 0.33405372
A46: MSFT | B46: 2010-03-31 00:00:00 | C46: 46445000000 | D46: 1219000000 | E46: 17250000000 | F46: 0.30664227

Sheet fh_fin_NVDA
A1: symbol | B1: period | C1: revenue | D1: capex | E1: free_cash_flow | F1: net_profit_margin
A2: NVDA | B2: 2025-10-26 00:00:00 | C2: 147811000000 | D2: 4758000000 | E2: 61772000000 | F2: 0.52165942
