Workbook

Sheet README
A1: Macro Intelligence Dashboard v4（机构级）
A4: 版本说明 | B4: 基于《基础数据v2.xlsx》升级，统一风险方向：估值越高越危险，情绪越亢奋越危险；并将盈利/质量/经济意外类指标从 Valuation 重分类到 Growth，提升 Dashboard 信号一致性。
A6: 本次更新 | B6: 1) Valuation / Sentiment 风险方向标准化；2) 修正主权基金净流入的情绪方向；3) Growth / Liquidity 分类更贴近机构监控框架。
A8: 工作簿结构 | B8: README / Controls / Dashboard / Indicators / Indicator_Map / 各指标清洗数据 Sheet
A10: 信号逻辑 | B10: 按 HigherBetter / HigherWorse / LowerBetter 三种方向自动生成 Trend、Signal、Score。
A12: 颜色图例 | B12: 蓝=结构/输入；黑=公式/结果；绿=内部链接/引用；橙=需关注；红=风险。
A15: 建议使用顺序
A16: 1) 在 Dashboard 看总览与分类得分
A17: 2) 在 Indicators 看逐指标趋势/信号
A18: 3) 在 Indicator_Map 按分类跳转明细
A19: 4) 在各数据 Sheet 看原始表格 + 图表

Sheet Controls
A1: Controls / 假设参数
A3: Parameter | B3: Value | C3: Description
A4: TrendThresholdPct | B4: 0.03 | C4: 若 Delta% 绝对值 >= 3%，则判断为显著变化
A5: PositiveScore | B5: 1 | C5: Positive 信号得分
A6: NeutralScore | B6: 0 | C6: Neutral 信号得分
A7: NegativeScore | B7: -1 | C7: Negative 信号得分
A8: ValuationRiskRule | B8: Higher = More Dangerous | C8: 估值越高，风险分数越偏负面
A9: SentimentRiskRule | B9: Higher = More Dangerous | C9: 情绪越高、越拥挤，风险分数越偏负面
A10: MethodologyUpdate | B10: v4 Reclassified Metrics | C10: 将盈利修正/经济意外/质量指标从估值类移至增长类
A11: Growth | B11: 1 | C11: Equal weight by default
A12: Inflation | B12: 1 | C12: Equal weight by default
A13: Liquidity | B13: 1 | C13: Equal weight by default
A14: Valuation | B14: 1 | C14: Equal weight by default
A15: Sentiment | B15: 1 | C15: Equal weight by default
A16: Housing | B16: 1 | C16: Equal weight by default

Sheet Dashboard
A1: Macro Intelligence Dashboard v4 / 机构级总览
A3: Methodology update | B3: Valuation↑ = more dangerous; Sentiment↑ = more dangerous. Quality / earnings revision / economic surprise metrics moved out of Valuation to keep category score direction consistent.
A4: Overall Score | B4: =ROUND(AVERAGE(B7:G7),2) -> -0.04 | D4: Macro Regime | E4: =IF(B4>=0.5,"Risk-On / Expansion",IF(B4<=-0.5,"Risk-Off / Tightening","Mixed / Transition")) -> Mixed / Transition
B6: Growth | C6: Inflation | D6: Liquidity | E6: Valuation | F6: Sentiment | G6: Housing
B7: =ROUND(AVERAGEIF(Indicators!$C$3:$C$36,"Growth",Indicators!$M$3:$M$36),2) -> 0.36 | C7: =ROUND(AVERAGEIF(Indicators!$C$3:$C$36,"Inflation",Indicators!$M$3:$M$36),2) -> 0.33 | D7: =ROUND(AVERAGEIF(Indicators!$C$3:$C$36,"Liquidity",Indicators!$M$3:$M$36),2) -> -0.57 | E7: =ROUND(AVERAGEIF(Indicators!$C$3:$C$36,"Valuation",Indicators!$M$3:$M$36),2) -> -1 | F7: =ROUND(AVERAGEIF(Indicators!$C$3:$C$36,"Sentiment",Indicators!$M$3:$M$36),2) -> 1 | G7: =ROUND(AVERAGEIF(Indicators!$C$3:$C$36,"Housing",Indicators!$M$3:$M$36),2) -> -0.33
B8: =IF(B7>0,"Supportive",IF(B7<0,"Headwind","Neutral")) -> Supportive | C8: =IF(C7>0,"Supportive",IF(C7<0,"Headwind","Neutral")) -> Supportive | D8: =IF(D7>0,"Supportive",IF(D7<0,"Headwind","Neutral")) -> Headwind | E8: =IF(E7>0,"Supportive / Cheap",IF(E7<0,"Headwind / Expensive","Neutral")) -> Headwind / Expensive | F8: =IF(F7>0,"Supportive / Fear",IF(F7<0,"Headwind / Greed","Neutral")) -> Supportive / Fear | G8: =IF(G7>0,"Supportive",IF(G7<0,"Headwind","Neutral")) -> Headwind
A11: Growth Indicators
A12: Indicator | B12: Latest | C12: Previous | D12: Delta | E12: DeltaPct | F12: Trend | G12: Signal | H12: Score
A13: =Indicators!A8 -> 纳斯达克营收增长 | B13: =Indicators!G8 -> 0.196 | C13: =Indicators!H8 -> 0.284 | D13: =Indicators!I8 -> -0.088 | E13: =Indicators!J8 -> -0.30985915 | F13: =Indicators!K8 -> Down | G13: =Indicators!L8 -> Negative | H13: =Indicators!M8 -> -1
A14: =Indicators!A24 -> GDP Now 预测 | B14: =Indicators!G24 -> 0.021 | C14: =Indicators!H24 -> 0.03 | D14: =Indicators!I24 -> -0.009 | E14: =Indicators!J24 -> -0.3 | F14: =Indicators!K24 -> Down | G14: =Indicators!L24 -> Negative | H14: =Indicators!M24 -> -1
A15: =Indicators!A25 -> St. Louis Fed Economic News Ind | B15: =Indicators!G25 -> 2.41 | C15: =Indicators!H25 -> -0.0017 | D15: =Indicators!I25 -> 2.4117 | E15: =Indicators!J25 -> 1418.6471 | F15: =Indicators!K25 -> Up | G15: =Indicators!L25 -> Positive | H15: =Indicators!M25 -> 1
A16: =Indicators!A26 -> ADS 商业景气指数(华尔街交易员股市应用稀缺的实时高频指引) | B16: =Indicators!G26 -> 0.32 | C16: =Indicators!H26 -> -0.35 | D16: =Indicators!I26 -> 0.67 | E16: =Indicators!J26 -> 1.9142857 | F16: =Indicators!K26 -> Up | G16: =Indicators!L26 -> Positive | H16: =Indicators!M26 -> 1
A17: =Indicators!A27 -> Lightcast 数据 | B17: =Indicators!G27 -> 74.5 | C17: =Indicators!H27 -> 72 | D17: =Indicators!I27 -> 2.5 | E17: =Indicators!J27 -> 0.034722222 | F17: =Indicators!K27 -> Up | G17: =Indicators!L27 -> Positive | H17: =Indicators!M27 -> 1
A18: =Indicators!A28 -> WARN Notice裁员数据 | B18: =Indicators!G28 -> 15.2 | C18: =Indicators!H28 -> 14.8 | D18: =Indicators!I28 -> 0.4 | E18: =Indicators!J28 -> 0.027027027 | F18: =Indicators!K28 -> Flat | G18: =Indicators!L28 -> Neutral | H18: =Indicators!M28 -> 0
A19: =Indicators!A29 -> ADP 新增就业人数 | B19: =Indicators!G29 -> 22000 | C19: =Indicators!H29 -> 22000 | D19: =Indicators!I29 -> 0 | E19: =Indicators!J29 -> 0 | F19: =Indicators!K29 -> Flat | G19: =Indicators!L29 -> Neutral | H19: =Indicators!M29 -> 0
A20: =Indicators!A30 -> RedBook 零售指数 | B20: =Indicators!G30 -> 6.9 | C20: =Indicators!H30 -> 0.076 | D20: =Indicators!I30 -> 6.824 | E20: =Indicators!J30 -> 89.789474 | F20: =Indicators!K30 -> Up | G20: =Indicators!L30 -> Positive | H20: =Indicators!M30 -> 1
A23: Inflation Indicators
A24: Indicator | B24: Latest | C24: Previous | D24: Delta | E24: DeltaPct | F24: Trend | G24: Signal | H24: Score
A25: =Indicators!A34 -> 薪资增速 (Average Hourly Earnings) | B25: =Indicators!G34 -> 3.8 | C25: =Indicators!H34 -> 3.7 | D25: =Indicators!I34 -> 0.1 | E25: =Indicators!J34 -> 0.027027027 | F25: =Indicators!K34 -> Flat | G25: =Indicators!L34 -> Neutral | H25: =Indicators!M34 -> 0
A26: =Indicators!A35 -> ISM 制造业和服务业价格指数 | B26: =Indicators!G35 -> 61.2 | C26: =Indicators!H35 -> 60.5 | D26: =Indicators!I35 -> 0.7 | E26: =Indicators!J35 -> 0.011570248 | F26: =Indicators!K35 -> Flat | G26: =Indicators!L35 -> Neutral | H26: =Indicators!M35 -> 0
A27: =Indicators!A36 -> 美国核心PCE物价指数 | B27: =Indicators!G36 -> 2.9 | C27: =Indicators!H36 -> 3 | D27: =Indicators!I36 -> -0.1 | E27: =Indicators!J36 -> -0.033333333 | F27: =Indicators!K36 -> Down | G27: =Indicators!L36 -> Positive | H27: =Indicators!M36 -> 1
A30: Liquidity Indicators
A31: Indicator | B31: Latest | C31: Previous | D31: Delta | E31: DeltaPct | F31: Trend | G31: Signal | H31: Score
A32: =Indicators!A5 -> TGA账户 | B32: =Indicators!G5 -> 871 | C32: =Indicators!H5 -> 820 | D32: =Indicators!I5 -> 51 | E32: =Indicators!J5 -> 0.062195122 | F32: =Indicators!K5 -> Up | G32: =Indicators!L5 -> Negative | H32: =Indicators!M5 -> -1
A33: =Indicators!A18 -> TGA账户余额 | B33: =Indicators!G18 -> 871 | C33: =Indicators!H18 -> 820 | D33: =Indicators!I18 -> 51 | E33: =Indicators!J18 -> 0.062195122 | F33: =Indicators!K18 -> Up | G33: =Indicators!L18 -> Negative | H33: =Indicators!M18 -> -1
A34: =Indicators!A19 -> SOFR-OIS 基差 | B34: =Indicators!G19 -> 18 | C34: =Indicators!H19 -> 16 | D34: =Indicators!I19 -> 2 | E34: =Indicators!J19 -> 0.125 | F34: =Indicators!K19 -> Up | G34: =Indicators!L19 -> Negative | H34: =Indicators!M19 -> -1
A35: =Indicators!A20 -> CARRY TO RISK RITIO | B35: =Indicators!G20 -> 0.12 | C35: =Indicators!H20 -> 0.15 | D35: =Indicators!I20 -> -0.03 | E35: =Indicators!J20 -> -0.2 | F35: =Indicators!K20 -> Down | G35: =Indicators!L20 -> Negative | H35: =Indicators!M20 -> -1
A36: =Indicators!A22 -> 彭博美国金融条件指数 | B36: =Indicators!G22 -> 0.85 | C36: =Indicators!H22 -> 1.02 | D36: =Indicators!I22 -> -0.17 | E36: =Indicators!J22 -> -0.16666667 | F36: =Indicators!K22 -> Down | G36: =Indicators!L22 -> Negative | H36: =Indicators!M22 -> -1
A37: =Indicators!A23 -> 芝加哥联储全国金融条件指数 (NFCI) | B37: =Indicators!G23 -> -0.48 | C37: =Indicators!H23 -> -0.36 | D37: =Indicators!I23 -> -0.12 | E37: =Indicators!J23 -> -0.33333333 | F37: =Indicators!K23 -> Down | G37: =Indicators!L23 -> Positive | H37: =Indicators!M23 -> 1
A40: Valuation Indicators
A41: Indicator | B41: Latest | C41: Previous | D41: Delta | E41: DeltaPct | F41: Trend | G41: Signal | H41: Score
A42: =Indicators!A3 -> 纳斯达克100毛利率五年趋势 | B42: =Indicators!G3 -> 0.548 | C42: =Indicators!H3 -> 0.545 | D42: =Indicators!I3 -> 0.003 | E42: =Indicators!J3 -> 0.0055045872 | F42: =Indicators!K3 -> Flat | G42: =Indicators!L3 -> Neutral | H42: =Indicators!M3 -> 0
A43: =Indicators!A4 -> 花旗标普500盈利上修动能指标 | B43: =Indicators!G4 -> 0.08 | C43: =Indicators!H4 -> -0.28 | D43: =Indicators!I4 -> 0.36 | E43: =Indicators!J4 -> 1.2857143 | F43: =Indicators!K4 -> Up | G43: =Indicators!L4 -> Positive | H43: =Indicators!M4 -> 1
A44: =Indicators!A6 -> 标普500盈余惊喜 | B44: =Indicators!G6 -> 0.225 | C44: =Indicators!H6 -> 0.182 | D44: =Indicators!I6 -> 0.043 | E44: =Indicators!J6 -> 0.23626374 | F44: =Indicators!K6 -> Up | G44: =Indicators!L6 -> Positive | H44: =Indicators!M6 -> 1
A45: =Indicators!A7 -> 标普500的roic-wacc | B45: =Indicators!G7 -> 0.098 | C45: =Indicators!H7 -> 0.103 | D45: =Indicators!I7 -> -0.005 | E45: =Indicators!J7 -> -0.048543689 | F45: =Indicators!K7 -> Down | G45: =Indicators!L7 -> Negative | H45: =Indicators!M7 -> -1
A46: =Indicators!A9 -> 标普500的ERP | B46: =Indicators!G9 -> 0.0289 | C46: =Indicators!H9 -> 0.0315 | D46: =Indicators!I9 -> -0.0026 | E46: =Indicators!J9 -> -0.082539683 | F46: =Indicators!K9 -> Down | G46: =Indicators!L9 -> Negative | H46: =Indicators!M9 -> -1
A47: =Indicators!A10 -> 标普500的花旗盈利修正指数 (ERI) | B47: =Indicators!G10 -> 0.55 | C47: =Indicators!H10 -> 0.48 | D47: =Indicators!I10 -> 0.07 | E47: =Indicators!J10 -> 0.14583333 | F47: =Indicators!K10 -> Up | G47: =Indicators!L10 -> Positive | H47: =Indicators!M10 -> 1
A48: =Indicators!A11 -> 标普500的花旗经济意外指数 (CESI US) | B48: =Indicators!G11 -> 40 | C48: =Indicators!H11 -> 20 | D48: =Indicators!I11 -> 20 | E48: =Indicators!J11 -> 1 | F48: =Indicators!K11 -> Up | G48: =Indicators!L11 -> Positive | H48: =Indicators!M11 -> 1
A49: =Indicators!A13 -> 标普500的现金流 PEG | B49: =Indicators!G13 -> 1.09 | C49: =Indicators!H13 -> 1.03 | D49: =Indicators!I13 -> 0.06 | E49: =Indicators!J13 -> 0.058252427 | F49: =Indicators!K13 -> Up | G49: =Indicators!L13 -> Negative | H49: =Indicators!M13 -> -1
A50: =Indicators!A14 -> 标普500的真实股东收益率（Total Shareholder | B50: =Indicators!G14 -> 0.0398 | C50: =Indicators!H14 -> 0.0447 | D50: =Indicators!I14 -> -0.0049 | E50: =Indicators!J14 -> -0.10961969 | F50: =Indicators!K14 -> Down | G50: =Indicators!L14 -> Negative | H50: =Indicators!M14 -> -1
...

Sheet Indicators
A1: Indicators / 全量指标库
A2: Indicator | B2: DataSheet | C2: Category | D2: Metric | E2: Frequency | F2: Orientation | G2: Latest | H2: Previous | I2: Delta | J2: DeltaPct | K2: Trend | L2: Signal | M2: Score | N2: Notes
A3: 纳斯达克100毛利率五年趋势 | B3: S01_纳斯达克100毛利率五年趋势 | C3: Growth | D3: 纳斯达克100毛利率五年趋势 | E3: Quarterly | F3: HigherBetter | G3: 0.548 | H3: 0.545 | I3: =IF(OR(G3="",H3=""),"",G3-H3) -> 0.003 | J3: =IF(OR(H3=0,H3=""),"",I3/ABS(H3)) -> 0.0055045872 | K3: =IF(OR(G3="",H3=""),"N/A",IF(ABS(J3)>=Controls!$B$4,IF(J3>0,"Up","Down"),"Flat")) -> Flat | L3: =IF(F3="HigherBetter",IF(K3="Up","Positive",IF(K3="Down","Negative","Neutral")),IF(F3="HigherWorse",IF(K3="Up","Negative",IF(K3="Down","Positive","Neutral")),IF(F3="LowerBetter",IF(K3="Up","Negative",IF(K3="Down","Positive","Neutral")),"Neutral"))) -> Neutral | M3: =IF(L3="Positive",Controls!$B$5,IF(L3="Negative",Controls!$B$7,Controls!$B$6)) -> 0 | N3: 重分类：质量/利润率改善更接近 Growth / Quality，而非估值过热
A4: 花旗标普500盈利上修动能指标 | B4: S02_花旗标普500盈利上修动能指标 | C4: Growth | D4: 花旗标普500盈利上修动能指标 (Citi ERI) | E4: Quarterly | F4: HigherBetter | G4: 0.08 | H4: -0.28 | I4: =IF(OR(G4="",H4=""),"",G4-H4) -> 0.36 | J4: =IF(OR(H4=0,H4=""),"",I4/ABS(H4)) -> 1.2857143 | K4: =IF(OR(G4="",H4=""),"N/A",IF(ABS(J4)>=Controls!$B$4,IF(J4>0,"Up","Down"),"Flat")) -> Up | L4: =IF(F4="HigherBetter",IF(K4="Up","Positive",IF(K4="Down","Negative","Neutral")),IF(F4="HigherWorse",IF(K4="Up","Negative",IF(K4="Down","Positive","Neutral")),IF(F4="LowerBetter",IF(K4="Up","Negative",IF(K4="Down","Positive","Neutral")),"Neutral"))) -> Positive | M4: =IF(L4="Positive",Controls!$B$5,IF(L4="Negative",Controls!$B$7,Controls!$B$6)) -> 1 | N4: 重分类：盈利上修动能属于盈利/增长改善
A5: TGA账户 | B5: S03_TGA账户 | C5: Liquidity | D5: TGA账户 | E5: Quarterly | F5: HigherWorse | G5: 871 | H5: 820 | I5: =IF(OR(G5="",H5=""),"",G5-H5) -> 51 | J5: =IF(OR(H5=0,H5=""),"",I5/ABS(H5)) -> 0.062195122 | K5: =IF(OR(G5="",H5=""),"N/A",IF(ABS(J5)>=Controls!$B$4,IF(J5>0,"Up","Down"),"Flat")) -> Up | L5: =IF(F5="HigherBetter",IF(K5="Up","Positive",IF(K5="Down","Negative","Neutral")),IF(F5="HigherWorse",IF(K5="Up","Negative",IF(K5="Down","Positive","Neutral")),IF(F5="LowerBetter",IF(K5="Up","Negative",IF(K5="Down","Positive","Neutral")),"Neutral"))) -> Negative | M5: =IF(L5="Positive",Controls!$B$5,IF(L5="Negative",Controls!$B$7,Controls!$B$6)) -> -1 | N5: Auto parsed and summarized from source sheet
A6: 标普500盈余惊喜 | B6: S04_标普500盈余惊喜 | C6: Growth | D6: 盈余惊喜幅度 (Surprise %) | E6: Quarterly | F6: HigherBetter | G6: 0.225 | H6: 0.182 | I6: =IF(OR(G6="",H6=""),"",G6-H6) -> 0.043 | J6: =IF(OR(H6=0,H6=""),"",I6/ABS(H6)) -> 0.23626374 | K6: =IF(OR(G6="",H6=""),"N/A",IF(ABS(J6)>=Controls!$B$4,IF(J6>0,"Up","Down"),"Flat")) -> Up | L6: =IF(F6="HigherBetter",IF(K6="Up","Positive",IF(K6="Down","Negative","Neutral")),IF(F6="HigherWorse",IF(K6="Up","Negative",IF(K6="Down","Positive","Neutral")),IF(F6="LowerBetter",IF(K6="Up","Negative",IF(K6="Down","Positive","Neutral")),"Neutral"))) -> Positive | M6: =IF(L6="Positive",Controls!$B$5,IF(L6="Negative",Controls!$B$7,Controls!$B$6)) -> 1 | N6: 重分类：盈余惊喜属于盈利动量
A7: 标普500的roic-wacc | B7: S05_标普500的roic-wacc | C7: Growth | D7: ROIC-WACC Spread (%) | E7: Quarterly | F7: HigherBetter | G7: 0.098 | H7: 0.103 | I7: =IF(OR(G7="",H7=""),"",G7-H7) -> -0.005 | J7: =IF(OR(H7=0,H7=""),"",I7/ABS(H7)) -> -0.048543689 | K7: =IF(OR(G7="",H7=""),"N/A",IF(ABS(J7)>=Controls!$B$4,IF(J7>0,"Up","Down"),"Flat")) -> Down | L7: =IF(F7="HigherBetter",IF(K7="Up","Positive",IF(K7="Down","Negative","Neutral")),IF(F7="HigherWorse",IF(K7="Up","Negative",IF(K7="Down","Positive","Neutral")),IF(F7="LowerBetter",IF(K7="Up","Negative",IF(K7="Down","Positive","Neutral")),"Neutral"))) -> Negative | M7: =IF(L7="Positive",Controls!$B$5,IF(L7="Negative",Controls!$B$7,Controls!$B$6)) -> -1 | N7: 重分类：ROIC-WACC 更接近质量/盈利能力
A8: 纳斯达克营收增长 | B8: S06_纳斯达克营收增长 | C8: Growth | D8: 营收同比增长率 (YoY Revenue Growth) | E8: Quarterly | F8: HigherBetter | G8: 0.196 | H8: 0.284 | I8: =IF(OR(G8="",H8=""),"",G8-H8) -> -0.088 | J8: =IF(OR(H8=0,H8=""),"",I8/ABS(H8)) -> -0.30985915 | K8: =IF(OR(G8="",H8=""),"N/A",IF(ABS(J8)>=Controls!$B$4,IF(J8>0,"Up","Down"),"Flat")) -> Down | L8: =IF(F8="HigherBetter",IF(K8="Up","Positive",IF(K8="Down","Negative","Neutral")),IF(F8="HigherWorse",IF(K8="Up","Negative",IF(K8="Down","Positive","Neutral")),IF(F8="LowerBetter",IF(K8="Up","Negative",IF(K8="Down","Positive","Neutral")),"Neutral"))) -> Negative | M8: =IF(L8="Positive",Controls!$B$5,IF(L8="Negative",Controls!$B$7,Controls!$B$6)) -> -1 | N8: Auto parsed and summarized from source sheet
A9: 标普500的ERP | B9: S07_标普500的ERP | C9: Valuation | D9: ERP (%) | E9: Quarterly | F9: HigherBetter | G9: 0.0289 | H9: 0.0315 | I9: =IF(OR(G9="",H9=""),"",G9-H9) -> -0.0026 | J9: =IF(OR(H9=0,H9=""),"",I9/ABS(H9)) -> -0.082539683 | K9: =IF(OR(G9="",H9=""),"N/A",IF(ABS(J9)>=Controls!$B$4,IF(J9>0,"Up","Down"),"Flat")) -> Down | L9: =IF(F9="HigherBetter",IF(K9="Up","Positive",IF(K9="Down","Negative","Neutral")),IF(F9="HigherWorse",IF(K9="Up","Negative",IF(K9="Down","Positive","Neutral")),IF(F9="LowerBetter",IF(K9="Up","Negative",IF(K9="Down","Positive","Neutral")),"Neutral"))) -> Negative | M9: =IF(L9="Positive",Controls!$B$5,IF(L9="Negative",Controls!$B$7,Controls!$B$6)) -> -1 | N9: Auto parsed and summarized from source sheet
A10: 标普500的花旗盈利修正指数 (ERI) | B10: S08_标普500的花旗盈利修正指数 (ERI) | C10: Growth | D10: 花旗盈利修正指数 (Citi ERI) | E10: Quarterly | F10: HigherBetter | G10: 0.55 | H10: 0.48 | I10: =IF(OR(G10="",H10=""),"",G10-H10) -> 0.07 | J10: =IF(OR(H10=0,H10=""),"",I10/ABS(H10)) -> 0.14583333 | K10: =IF(OR(G10="",H10=""),"N/A",IF(ABS(J10)>=Controls!$B$4,IF(J10>0,"Up","Down"),"Flat")) -> Up | L10: =IF(F10="HigherBetter",IF(K10="Up","Positive",IF(K10="Down","Negative","Neutral")),IF(F10="HigherWorse",IF(K10="Up","Negative",IF(K10="Down","Positive","Neutral")),IF(F10="LowerBetter",IF(K10="Up","Negative",IF(K10="Down","Positive","Neutral")),"Neutral"))) -> Positive | M10: =IF(L10="Positive",Controls!$B$5,IF(L10="Negative",Controls!$B$7,Controls!$B$6)) -> 1 | N10: 重分类：ERI 属于盈利修正动量
A11: 标普500的花旗经济意外指数 (CESI US) | B11: S09_标普500的花旗经济意外指数 (CESI US) | C11: Growth | D11: 花旗经济意外指数 (CESI US) | E11: Quarterly | F11: HigherBetter | G11: 40 | H11: 20 | I11: =IF(OR(G11="",H11=""),"",G11-H11) -> 20 | J11: =IF(OR(H11=0,H11=""),"",I11/ABS(H11)) -> 1 | K11: =IF(OR(G11="",H11=""),"N/A",IF(ABS(J11)>=Controls!$B$4,IF(J11>0,"Up","Down"),"Flat")) -> Up | L11: =IF(F11="HigherBetter",IF(K11="Up","Positive",IF(K11="Down","Negative","Neutral")),IF(F11="HigherWorse",IF(K11="Up","Negative",IF(K11="Down","Positive","Neutral")),IF(F11="LowerBetter",IF(K11="Up","Negative",IF(K11="Down","Positive","Neutral")),"Neutral"))) -> Positive | M11: =IF(L11="Positive",Controls!$B$5,IF(L11="Negative",Controls!$B$7,Controls!$B$6)) -> 1 | N11: 重分类：CESI 属于经济意外/增长脉冲
A12: 主权基金净流入情况 | B12: S10_主权基金净流入情况 | C12: Sentiment | D12: 净流入估算 (Est. Net Inflow) | E12: Quarterly | F12: HigherWorse | G12: 50.2 | H12: 55.6 | I12: =IF(OR(G12="",H12=""),"",G12-H12) -> -5.4 | J12: =IF(OR(H12=0,H12=""),"",I12/ABS(H12)) -> -0.097122302 | K12: =IF(OR(G12="",H12=""),"N/A",IF(ABS(J12)>=Controls!$B$4,IF(J12>0,"Up","Down"),"Flat")) -> Down | L12: =IF(F12="HigherBetter",IF(K12="Up","Positive",IF(K12="Down","Negative","Neutral")),IF(F12="HigherWorse",IF(K12="Up","Negative",IF(K12="Down","Positive","Neutral")),IF(F12="LowerBetter",IF(K12="Up","Negative",IF(K12="Down","Positive","Neutral")),"Neutral"))) -> Positive | M12: =IF(L12="Positive",Controls!$B$5,IF(L12="Negative",Controls!$B$7,Controls!$B$6)) -> 1 | N12: 方向修正：净流入越强，通常代表风险偏好越热/更拥挤
A13: 标普500的现金流 PEG | B13: S11_标普500的现金流 PEG | C13: Valuation | D13: 现金流 PEG | E13: Quarterly | F13: HigherWorse | G13: 1.09 | H13: 1.03 | I13: =IF(OR(G13="",H13=""),"",G13-H13) -> 0.06 | J13: =IF(OR(H13=0,H13=""),"",I13/ABS(H13)) -> 0.058252427 | K13: =IF(OR(G13="",H13=""),"N/A",IF(ABS(J13)>=Controls!$B$4,IF(J13>0,"Up","Down"),"Flat")) -> Up | L13: =IF(F13="HigherBetter",IF(K13="Up","Positive",IF(K13="Down","Negative","Neutral")),IF(F13="HigherWorse",IF(K13="Up","Negative",IF(K13="Down","Positive","Neutral")),IF(F13="LowerBetter",IF(K13="Up","Negative",IF(K13="Down","Positive","Neutral")),"Neutral"))) -> Negative | M13: =IF(L13="Positive",Controls!$B$5,IF(L13="Negative",Controls!$B$7,Controls!$B$6)) -> -1 | N13: Auto parsed and summarized from source sheet
A14: 标普500的真实股东收益率（Total Shareholder | B14: S12_标普500的真实股东收益率（Total Shareho | C14: Valuation | D14: TSY (A+B) | E14: Quarterly | F14: HigherBetter | G14: 0.0398 | H14: 0.0447 | I14: =IF(OR(G14="",H14=""),"",G14-H14) -> -0.0049 | J14: =IF(OR(H14=0,H14=""),"",I14/ABS(H14)) -> -0.10961969 | K14: =IF(OR(G14="",H14=""),"N/A",IF(ABS(J14)>=Controls!$B$4,IF(J14>0,"Up","Down"),"Flat")) -> Down | L14: =IF(F14="HigherBetter",IF(K14="Up","Positive",IF(K14="Down","Negative","Neutral")),IF(F14="HigherWorse",IF(K14="Up","Negative",IF(K14="Down","Positive","Neutral")),IF(F14="LowerBetter",IF(K14="Up","Negative",IF(K14="Down","Positive","Neutral")),"Neutral"))) -> Negative | M14: =IF(L14="Positive",Controls!$B$5,IF(L14="Negative",Controls!$B$7,Controls!$B$6)) -> -1 | N14: Auto parsed and summarized from source sheet
... A36: 美国核心PCE物价指数 | B36: S34_美国核心PCE物价指数 | C36: Inflation | D36: 美国核心PCE物价指数 | E36: Monthly | F36: HigherWorse | G36: 2.9 | H36: 3 | I36: =IF(OR(G36="",H36=""),"",G36-H36) -> -0.1 | J36: =IF(OR(H36=0,H36=""),"",I36/ABS(H36)) -> -0.033333333 | K36: =IF(OR(G36="",H36=""),"N/A",IF(ABS(J36)>=Controls!$B$4,IF(J36>0,"Up","Down"),"Flat")) -> Down | L36: =IF(F36="HigherBetter",IF(K36="Up","Positive",IF(K36="Down","Negative","Neutral")),IF(F36="HigherWorse",IF(K36="Up","Negative",IF(K36="Down","Positive","Neutral")),IF(F36="LowerBetter",IF(K36="Up","Negative",IF(K36="Down","Positive","Neutral")),"Neutral"))) -> Positive | M36: =IF(L36="Positive",Controls!$B$5,IF(L36="Negative",Controls!$B$7,Controls!$B$6)) -> 1 | N36: Auto parsed and summarized from source sheet

Sheet Indicator_Map
A1: Indicator Map / 分类与跳转
A2: Indicator | B2: DataSheet | C2: Category | D2: PrimaryMetric | E2: Frequency | F2: Orientation | G2: ObsCount
A3: 纳斯达克100毛利率五年趋势 | B3: S01_纳斯达克100毛利率五年趋势 | C3: Growth | D3: 纳斯达克100毛利率五年趋势 | E3: Quarterly | F3: HigherBetter | G3: 20
A4: 花旗标普500盈利上修动能指标 | B4: S02_花旗标普500盈利上修动能指标 | C4: Growth | D4: 花旗标普500盈利上修动能指标 (Citi ERI) | E4: Quarterly | F4: HigherBetter | G4: 6
A5: TGA账户 | B5: S03_TGA账户 | C5: Liquidity | D5: TGA账户 | E5: Quarterly | F5: HigherWorse | G5: 21
A6: 标普500盈余惊喜 | B6: S04_标普500盈余惊喜 | C6: Growth | D6: 盈余惊喜幅度 (Surprise %) | E6: Quarterly | F6: HigherBetter | G6: 20
A7: 标普500的roic-wacc | B7: S05_标普500的roic-wacc | C7: Growth | D7: ROIC-WACC Spread (%) | E7: Quarterly | F7: HigherBetter | G7: 20
A8: 纳斯达克营收增长 | B8: S06_纳斯达克营收增长 | C8: Growth | D8: 营收同比增长率 (YoY Revenue Growth) | E8: Quarterly | F8: HigherBetter | G8: 20
A9: 标普500的ERP | B9: S07_标普500的ERP | C9: Valuation | D9: ERP (%) | E9: Quarterly | F9: HigherBetter | G9: 20
A10: 标普500的花旗盈利修正指数 (ERI) | B10: S08_标普500的花旗盈利修正指数 (ERI) | C10: Growth | D10: 花旗盈利修正指数 (Citi ERI) | E10: Quarterly | F10: HigherBetter | G10: 20
A11: 标普500的花旗经济意外指数 (CESI US) | B11: S09_标普500的花旗经济意外指数 (CESI US) | C11: Growth | D11: 花旗经济意外指数 (CESI US) | E11: Quarterly | F11: HigherBetter | G11: 20
A12: 主权基金净流入情况 | B12: S10_主权基金净流入情况 | C12: Sentiment | D12: 净流入估算 (Est. Net Inflow) | E12: Quarterly | F12: HigherWorse | G12: 20
A13: 标普500的现金流 PEG | B13: S11_标普500的现金流 PEG | C13: Valuation | D13: 现金流 PEG | E13: Quarterly | F13: HigherWorse | G13: 20
A14: 标普500的真实股东收益率（Total Shareholder | B14: S12_标普500的真实股东收益率（Total Shareho | C14: Valuation | D14: TSY (A+B) | E14: Quarterly | F14: HigherBetter | G14: 20
... A36: 美国核心PCE物价指数 | B36: S34_美国核心PCE物价指数 | C36: Inflation | D36: 美国核心PCE物价指数 | E36: Monthly | F36: HigherWorse | G36: 61

Sheet S01_纳斯达克100毛利率五年趋势
A1: 纳斯达克100毛利率五年趋势
A3: Category | B3: Valuation | C3: Primary Metric | D3: 纳斯达克100毛利率五年趋势 | E3: Frequency | F3: Quarterly | H3: Back to Dashboard
A4: Orientation | B4: HigherBetter | C4: Latest | D4: 0.548 | E4: Previous | F4: 0.545
A7: 年份 | B7: 第一季度 (Q1) | C7: 第二季度 (Q2) | D7: 第三季度 (Q3) | E7: 第四季度 (Q4) | F7: 年度趋势说明 | J7: TimePoint | K7: Series
A8: 2021 | B8: 0.508 | C8: 0.512 | D8: 0.515 | E8: 0.518 | F8: 疫情期间云服务和电子产品需求爆发，毛利稳步扩张。 | J8: 2021-第一季度 (Q1) | K8: 0.508
A9: 2022 | B9: 0.505 | C9: 0.498 | D9: 0.492 | E9: 0.495 | F9: 受高通胀、供应链中断及加息影响，硬件成本上升，毛利探底。 | J9: 2021-第二季度 (Q2) | K9: 0.512
A10: 2023 | B10: 0.502 | C10: 0.51 | D10: 0.518 | E10: 0.525 | F10: 科技行业“效率之年”，通过裁员降本，且AI算力需求开始起量。 | J10: Data Source | K10: Uploaded file: 基础数据v2.xlsx
A11: 2024 | B11: 0.528 | C11: 0.532 | D11: 0.535 | E11: 0.539 | F11: AI爆发期。英伟达、博通等高毛利芯片股权重影响力激增。 | J11: Transform | K11: Zero removed; numeric-like text parsed for analytics
A12: 2025 | B12: 0.538 | C12: 0.542 | D12: 0.545 | E12: 0.548 | F12: 软件AI化转型提升边际利润，指数整体毛利率处于历史高点。 | J12: 2022-第一季度 (Q1) | K12: 0.505
J13: 2022-第二季度 (Q2) | K13: 0.498
J14: 2022-第三季度 (Q3) | K14: 0.492
J15: 2022-第四季度 (Q4) | K15: 0.495
J16: 2023-第一季度 (Q1) | K16: 0.502
J17: 2023-第二季度 (Q2) | K17: 0.51
J18: 2023-第三季度 (Q3) | K18: 0.518
J19: 2023-第四季度 (Q4) | K19: 0.525
J20: 2024-第一季度 (Q1) | K20: 0.528
J21: 2024-第二季度 (Q2) | K21: 0.532
J22: 2024-第三季度 (Q3) | K22: 0.535
J23: 2024-第四季度 (Q4) | K23: 0.539
J24: 2025-第一季度 (Q1) | K24: 0.538
... J27: 2025-第四季度 (Q4) | K27: 0.548

Sheet S02_花旗标普500盈利上修动能指标
A1: 花旗标普500盈利上修动能指标
A3: Category | B3: Valuation | C3: Primary Metric | D3: 花旗标普500盈利上修动能指标 (Citi ERI) | E3: Frequency | F3: Quarterly | H3: Back to Dashboard
A4: Orientation | B4: HigherBetter | C4: Latest | D4: 0.08 | E4: Previous | F4: -0.28
A7: 季度 (Quarter) | B7: 花旗标普500盈利上修动能指标 (Citi ERI) | C7: 市场阶段/主要事件 | J7: TimePoint | K7: Series
A8: 2021 Q1-Q2 | B8: +0.42 ~ +0.55 | C8: 疫情后强劲复苏，由于低基数和财政刺激，盈测大幅上修。 | J8: 1 | K8: 0.42
A9: 2022 Q2-Q4 | B9: -0.18 ~ -0.45 | C9: 通胀高企与激进加息，能源以外行业盈测被显著下调，衰退担忧加剧。 | J9: 2 | K9: -0.18
A10: 2023 Q2 | B10: 0.08 | C10: AI浪潮开启，以英伟达为首的科技股带动盈测动能止跌回升。 | J10: Data Source | K10: Uploaded file: 基础数据v2.xlsx
A11: 2024 Q3 | B11: 0.38 | C11: 动能峰值，AI基础设施支出爆发，头部科技股（Mag 7）盈测密集上修。 | J11: Transform | K11: Zero removed; numeric-like text parsed for analytics
A12: 2025 Q2 | B12: -0.28 | C12: 政策冲击，受4月初关税预期影响，盈测出现阶段性剧烈下修，后随政策缓解回升。 | J12: 5 | K12: -0.28
A13: 2026 Q1 | B13: 0.08 | C13: 平稳期，当前盈测动能处于中性偏正向，市场关注重点转向2026年业绩增长。 | J13: 6 | K13: 0.08

Sheet S03_TGA账户
A1: TGA账户
A3: Category | B3: Liquidity | C3: Primary Metric | D3: TGA账户 | E3: Frequency | F3: Quarterly | H3: Back to Dashboard
A4: Orientation | B4: HigherWorse | C4: Latest | D4: 871 | E4: Previous | F4: 820
A7: 年份 | B7: 第一季度 (Q1) | C7: 第二季度 (Q2) | D7: 第三季度 (Q3) | E7: 第四季度 (Q4) | J7: TimePoint | K7: Series
A8: 2021 | B8: 1122 | C8: 852 | D8: 215 | E8: 406 | J8: 2021-第一季度 (Q1) | K8: 1122
A9: 2022 | B9: 628 | C9: 757 | D9: 636 | E9: 447 | J9: 2021-第二季度 (Q2) | K9: 852
A10: 2023 | B10: 178 | C10: 402 | D10: 661 | E10: 769 | J10: Data Source | K10: Uploaded file: 基础数据v2.xlsx
A11: 2024 | B11: 745 | C11: 755 | D11: 818 | E11: 702 | J11: Transform | K11: Zero removed; numeric-like text parsed for analytics
A12: 2025 | B12: $325* | C12: 650 | D12: 835 | E12: 820 | J12: 2022-第一季度 (Q1) | K12: 628
A13: 2026 | B13: $871 (最新) | C13: - | D13: - | E13: - | J13: 2022-第二季度 (Q2) | K13: 757
J14: 2022-第三季度 (Q3) | K14: 636
J15: 2022-第四季度 (Q4) | K15: 447
J16: 2023-第一季度 (Q1) | K16: 178
J17: 2023-第二季度 (Q2) | K17: 402
J18: 2023-第三季度 (Q3) | K18: 661
J19: 2023-第四季度 (Q4) | K19: 769
J20: 2024-第一季度 (Q1) | K20: 745
J21: 2024-第二季度 (Q2) | K21: 755
J22: 2024-第三季度 (Q3) | K22: 818
J23: 2024-第四季度 (Q4) | K23: 702
J24: 2025-第一季度 (Q1) | K24: 325
J25: 2025-第二季度 (Q2) | K25: 650
... J28: 2026-第一季度 (Q1) | K28: 871

Sheet S04_标普500盈余惊喜
A1: 标普500盈余惊喜
A3: Category | B3: Valuation | C3: Primary Metric | D3: 盈余惊喜幅度 (Surprise %) | E3: Frequency | F3: Quarterly | H3: Back to Dashboard
A4: Orientation | B4: HigherBetter | C4: Latest | D4: 0.225 | E4: Previous | F4: 0.182
A7: 季度 (Quarter) | B7: 盈余惊喜幅度 (Surprise %) | C7: 超预期公司占比 (Beat Rate %) | J7: TimePoint | K7: Series
A8: 2025 Q4 | B8: 0.068 | C8: 0.73 | J8: 1 | K8: 0.068
A9: 2025 Q3 | B9: 0.059 | C9: 0.82 | J9: 2 | K9: 0.059
A10: 2025 Q2 | B10: 0.084 | C10: 0.81 | J10: Data Source | K10: Uploaded file: 基础数据v2.xlsx
A11: 2025 Q1 | B11: 0.085 | C11: 0.78 | J11: Transform | K11: Zero removed; numeric-like text parsed for analytics
A12: 2024 Q4 | B12: 0.073 | C12: 0.76 | J12: 5 | K12: 0.073
A13: 2024 Q3 | B13: 0.063 | C13: 0.75 | J13: 6 | K13: 0.063
A14: 2024 Q2 | B14: 0.109 | C14: 0.79 | J14: 7 | K14: 0.109
A15: 2024 Q1 | B15: 0.088 | C15: 0.74 | J15: 8 | K15: 0.088
A16: 2023 Q4 | B16: 0.067 | C16: 0.76 | J16: 9 | K16: 0.067
A17: 2023 Q3 | B17: 0.081 | C17: 0.81 | J17: 10 | K17: 0.081
A18: 2023 Q2 | B18: 0.079 | C18: 0.79 | J18: 11 | K18: 0.079
A19: 2023 Q1 | B19: 0.065 | C19: 0.77 | J19: 12 | K19: 0.065
A20: 2022 Q4 | B20: 0.013 | C20: 0.68 | J20: 13 | K20: 0.013
A21: 2022 Q3 | B21: 0.032 | C21: 0.71 | J21: 14 | K21: 0.032
A22: 2022 Q2 | B22: 0.051 | C22: 0.75 | J22: 15 | K22: 0.051
A23: 2022 Q1 | B23: 0.046 | C23: 0.76 | J23: 16 | K23: 0.046
... A27: 2021 Q1 | B27: 0.225 | C27: 0.86 | J27: 20 | K27: 0.225

Sheet S05_标普500的roic-wacc
A1: 标普500的roic-wacc
A3: Category | B3: Valuation | C3: Primary Metric | D3: ROIC-WACC Spread (%) | E3: Frequency | F3: Quarterly | H3: Back to Dashboard
A4: Orientation | B4: HigherBetter | C4: Latest | D4: 0.098 | E4: Previous | F4: 0.103
A7: 季度 (Quarter) | B7: 平均 ROIC (%) | C7: 平均 WACC (%) | D7: ROIC-WACC Spread (%) | J7: TimePoint | K7: Series
A8: 2025 Q4 | B8: 0.178 | C8: 0.082 | D8: 0.096 | J8: 1 | K8: 0.096
A9: 2025 Q3 | B9: 0.175 | C9: 0.084 | D9: 0.091 | J9: 2 | K9: 0.091
A10: 2025 Q2 | B10: 0.172 | C10: 0.083 | D10: 0.089 | J10: Data Source | K10: Uploaded file: 基础数据v2.xlsx
A11: 2025 Q1 | B11: 0.169 | C11: 0.081 | D11: 0.088 | J11: Transform | K11: Zero removed; numeric-like text parsed for analytics
A12: 2024 Q4 | B12: 0.168 | C12: 0.079 | D12: 0.089 | J12: 5 | K12: 0.089
A13: 2024 Q3 | B13: 0.165 | C13: 0.08 | D13: 0.085 | J13: 6 | K13: 0.085
A14: 2024 Q2 | B14: 0.163 | C14: 0.082 | D14: 0.081 | J14: 7 | K14: 0.081
A15: 2024 Q1 | B15: 0.16 | C15: 0.085 | D15: 0.075 | J15: 8 | K15: 0.075
A16: 2023 Q4 | B16: 0.158 | C16: 0.086 | D16: 0.072 | J16: 9 | K16: 0.072
A17: 2023 Q3 | B17: 0.156 | C17: 0.088 | D17: 0.068 | J17: 10 | K17: 0.068
A18: 2023 Q2 | B18: 0.154 | C18: 0.085 | D18: 0.069 | J18: 11 | K18: 0.069
A19: 2023 Q1 | B19: 0.151 | C19: 0.082 | D19: 0.069 | J19: 12 | K19: 0.069
A20: 2022 Q4 | B20: 0.149 | C20: 0.08 | D20: 0.069 | J20: 13 | K20: 0.069
A21: 2022 Q3 | B21: 0.152 | C21: 0.078 | D21: 0.074 | J21: 14 | K21: 0.074
A22: 2022 Q2 | B22: 0.155 | C22: 0.072 | D22: 0.083 | J22: 15 | K22: 0.083
A23: 2022 Q1 | B23: 0.158 | C23: 0.065 | D23: 0.093 | J23: 16 | K23: 0.093
... A27: 2021 Q1 | B27: 0.152 | C27: 0.054 | D27: 0.098 | J27: 20 | K27: 0.098

Sheet S06_纳斯达克营收增长
A1: 纳斯达克营收增长
A3: Category | B3: Growth | C3: Primary Metric | D3: 营收同比增长率 (YoY Revenue Growth) | E3: Frequency | F3: Quarterly | H3: Back to Dashboard
A4: Orientation | B4: HigherBetter | C4: Latest | D4: 0.196 | E4: Previous | F4: 0.284
A7: 季度 (Quarter) | B7: 营收同比增长率 (YoY Revenue Growth) | C7: 备注 / 驱动因素 | J7: TimePoint | K7: Series
A8: 2025 Q4 | B8: 0.124 | C8: AI 基础设施需求与 SaaS 订阅增长 | J8: AI 基础设施需求与 SaaS 订阅增长 | K8: 0.124
A9: 2025 Q3 | B9: 0.118 | C9: 云计算服务反弹及半导体板块走强 | J9: 云计算服务反弹及半导体板块走强 | K9: 0.118
A10: 2025 Q2 | B10: 0.105 | C10: 企业端 IT 支出回暖 | J10: Data Source | K10: Uploaded file: 基础数据v2.xlsx
A11: 2025 Q1 | B11: 0.097 | C11: 宏观经济软着陆预期下的消费电子复苏 | J11: Transform | K11: Zero removed; numeric-like text parsed for analytics
A12: 2024 Q4 | B12: 0.086 | C12: AI 硬件（如 GPU）开始大幅贡献营收 | J12: AI 硬件（如 GPU）开始大幅贡献营收 | K12: 0.086
A13: 2024 Q3 | B13: 0.072 | C13: 软件行业受高利率压制，增长略有放缓 | J13: 软件行业受高利率压制，增长略有放缓 | K13: 0.072
A14: 2024 Q2 | B14: 0.065 | C14: 广告市场（Meta/Alphabet）稳步回升 | J14: 7 | K14: 0.065
A15: 2024 Q1 | B15: 0.059 | C15: 后疫情时代高基数压力减轻 | J15: 后疫情时代高基数压力减轻 | K15: 0.059
A16: 2023 Q4 | B16: 0.048 | C16: 经济衰退担忧下的企业支出紧缩期 | J16: 经济衰退担忧下的企业支出紧缩期 | K16: 0.048
A17: 2023 Q3 | B17: 0.039 | C17: 过去5年低点，高利率环境影响深远 | J17: 过去5年低点，高利率环境影响深远 | K17: 0.039
A18: 2023 Q2 | B18: 0.042 | C18: 消费者支出从商品向服务转移 | J18: 消费者支出从商品向服务转移 | K18: 0.042
A19: 2023 Q1 | B19: 0.051 | C19: 硅谷银行危机后的短期市场波动 | J19: 硅谷银行危机后的短期市场波动 | K19: 0.051
A20: 2022 Q4 | B20: 0.073 | C20: 通胀见顶，美联储激进加息初期 | J20: 通胀见顶，美联储激进加息初期 | K20: 0.073
A21: 2022 Q3 | B21: 0.098 | C21: 供应链问题缓解，硬件交付加快 | J21: 供应链问题缓解，硬件交付加快 | K21: 0.098
A22: 2022 Q2 | B22: 0.125 | C22: 能源价格上涨与美元走强干扰增长 | J22: 能源价格上涨与美元走强干扰增长 | K22: 0.125
A23: 2022 Q1 | B23: 0.142 | C23: 疫情红利逐渐消退的过渡期 | J23: 疫情红利逐渐消退的过渡期 | K23: 0.142
... A27: 2021 Q1 | B27: 0.196 | C27: 远程办公硬件与软件需求激增 | J27: 远程办公硬件与软件需求激增 | K27: 0.196

Sheet S07_标普500的ERP
A1: 标普500的ERP
A3: Category | B3: Valuation | C3: Primary Metric | D3: ERP (%) | E3: Frequency | F3: Quarterly | H3: Back to Dashboard
A4: Orientation | B4: HigherBetter | C4: Latest | D4: 0.0289 | E4: Previous | F4: 0.0315
A7: 季度 (Quarter) | B7: 标普500 PE (Forward) | C7: 10Y 国债收益率 (%) | D7: ERP (%) | E7: 10年历史分位数 (%) | J7: TimePoint | K7: Series
A8: 2025 Q4 | B8: 22.1 | C8: 0.042 | D8: 0.0032 | E8: 0.085 | J8: 1 | K8: 0.0032
A9: 2025 Q3 | B9: 21.8 | C9: 0.044 | D9: 0.0019 | E9: 0.042 | J9: 2 | K9: 0.0019
A10: 2025 Q2 | B10: 21.2 | C10: 0.043 | D10: 0.0042 | E10: 0.121 | J10: Data Source | K10: Uploaded file: 基础数据v2.xlsx
A11: 2025 Q1 | B11: 20.8 | C11: 0.041 | D11: 0.0071 | E11: 0.185 | J11: Transform | K11: Zero removed; numeric-like text parsed for analytics
A12: 2024 Q4 | B12: 20.5 | C12: 0.039 | D12: 0.0098 | E12: 0.242 | J12: 5 | K12: 0.0098
A13: 2024 Q3 | B13: 19.8 | C13: 0.04 | D13: 0.0105 | E13: 0.268 | J13: 6 | K13: 0.0105
A14: 2024 Q2 | B14: 19.2 | C14: 0.045 | D14: 0.0071 | E14: 0.184 | J14: 7 | K14: 0.0071
A15: 2024 Q1 | B15: 18.9 | C15: 0.043 | D15: 0.0099 | E15: 0.245 | J15: 8 | K15: 0.0099
A16: 2023 Q4 | B16: 18.1 | C16: 0.041 | D16: 0.0142 | E16: 0.352 | J16: 9 | K16: 0.0142
A17: 2023 Q3 | B17: 17.5 | C17: 0.046 | D17: 0.0111 | E17: 0.286 | J17: 10 | K17: 0.0111
A18: 2023 Q2 | B18: 18.2 | C18: 0.038 | D18: 0.0169 | E18: 0.421 | J18: 11 | K18: 0.0169
A19: 2023 Q1 | B19: 17.2 | C19: 0.035 | D19: 0.0231 | E19: 0.584 | J19: 12 | K19: 0.0231
A20: 2022 Q4 | B20: 16.5 | C20: 0.039 | D20: 0.0216 | E20: 0.542 | J20: 13 | K20: 0.0216
A21: 2022 Q3 | B21: 15.2 | C21: 0.038 | D21: 0.0278 | E21: 0.685 | J21: 14 | K21: 0.0278
A22: 2022 Q2 | B22: 15.8 | C22: 0.03 | D22: 0.0333 | E22: 0.824 | J22: 15 | K22: 0.0333
A23: 2022 Q1 | B23: 18.5 | C23: 0.023 | D23: 0.0311 | E23: 0.786 | J23: 16 | K23: 0.0311
... A27: 2021 Q1 | B27: 21.8 | C27: 0.017 | D27: 0.0289 | E27: 0.724 | J27: 20 | K27: 0.0289

Sheet S08_标普500的花旗盈利修正指数 (ERI)
A1: 标普500的花旗盈利修正指数 (ERI)
A3: Category | B3: Valuation | C3: Primary Metric | D3: 花旗盈利修正指数 (Citi ERI) | E3: Frequency | F3: Quarterly | H3: Back to Dashboard
A4: Orientation | B4: HigherBetter | C4: Latest | D4: 0.55 | E4: Previous | F4: 0.48
A7: 季度 (Quarter) | B7: 花旗盈利修正指数 (Citi ERI) | C7: 修正趋势 (Market Sentiment) | J7: TimePoint | K7: Series
A8: 2025 Q4 | B8: 0.08 | C8: 小幅上修 (AI 相关板块情绪企稳) | J8: 小幅上修 (AI 相关板块情绪企稳) | K8: 0.08
A9: 2025 Q3 | B9: -0.05 | C9: 小幅下修 (周期性板块担忧) | J9: 小幅下修 (周期性板块担忧) | K9: -0.05
A10: 2025 Q2 | B10: 0.12 | C10: 上修 (利润率扩张超预期) | J10: Data Source | K10: Uploaded file: 基础数据v2.xlsx
A11: 2025 Q1 | B11: 0.15 | C11: 上修 (开年预期普遍乐观) | J11: Transform | K11: Zero removed; numeric-like text parsed for analytics
A12: 2024 Q4 | B12: 0.02 | C12: 持平 (多空修正相抵) | J12: 持平 (多空修正相抵) | K12: 0.02
A13: 2024 Q3 | B13: -0.12 | C13: 下修 (受软件行业财报低迷拖累) | J13: 下修 (受软件行业财报低迷拖累) | K13: -0.12
A14: 2024 Q2 | B14: 0.05 | C14: 小幅上修 (大型科技股盈利强劲) | J14: 小幅上修 (大型科技股盈利强劲) | K14: 0.05
A15: 2024 Q1 | B15: -0.08 | C15: 小幅下修 (典型季节性审慎) | J15: 小幅下修 (典型季节性审慎) | K15: -0.08
A16: 2023 Q4 | B16: -0.18 | C16: 明显下修 (对衰退风险的最后担忧) | J16: 明显下修 (对衰退风险的最后担忧) | K16: -0.18
A17: 2023 Q3 | B17: 0.04 | C17: 小幅上修 (三季度财报表现韧性) | J17: 小幅上修 (三季度财报表现韧性) | K17: 0.04
A18: 2023 Q2 | B18: -0.02 | C18: 持平 (银行业危机后的观察期) | J18: 持平 (银行业危机后的观察期) | K18: -0.02
A19: 2023 Q1 | B19: -0.25 | C19: 明显下修 (地区性银行危机冲击) | J19: 明显下修 (地区性银行危机冲击) | K19: -0.25
A20: 2022 Q4 | B20: -0.35 | C20: 极度下修 (能源价格及高通胀压力) | J20: 极度下修 (能源价格及高通胀压力) | K20: -0.35
A21: 2022 Q3 | B21: -0.28 | C21: 明显下修 (加息周期全速开启) | J21: 明显下修 (加息周期全速开启) | K21: -0.28
A22: 2022 Q2 | B22: -0.15 | C22: 下修 (库存积压及成本上升) | J22: 下修 (库存积压及成本上升) | K22: -0.15
A23: 2022 Q1 | B23: 0.1 | C23: 小幅上修 (疫情后复苏余温) | J23: 小幅上修 (疫情后复苏余温) | K23: 0.1
... A27: 2021 Q1 | B27: 0.55 | C27: 强劲上修 (政策刺激与低基数效应) | J27: 强劲上修 (政策刺激与低基数效应) | K27: 0.55

Sheet S09_标普500的花旗经济意外指数 (CESI US)
A1: 标普500的花旗经济意外指数 (CESI US)
A3: Category | B3: Valuation | C3: Primary Metric | D3: 花旗经济意外指数 (CESI US) | E3: Frequency | F3: Quarterly | H3: Back to Dashboard
A4: Orientation | B4: HigherBetter | C4: Latest | D4: 40 | E4: Previous | F4: 20
A7: 季度 (Quarter) | B7: 花旗经济意外指数 (CESI US) | C7: 经济数据 vs 预期表现 | J7: TimePoint | K7: Series
A8: 2025 Q4 | B8: 12 | C8: 小幅好于预期 (经济软着陆迹象) | J8: 小幅好于预期 (经济软着陆迹象) | K8: 12
A9: 2025 Q3 | B9: 5 | C9: 基本持平 (政策切换期的观望) | J9: 基本持平 (政策切换期的观望) | K9: 5
A10: 2025 Q2 | B10: 10 | C10: 稳健好于预期 (制造业回暖) | J10: Data Source | K10: Uploaded file: 基础数据v2.xlsx
A11: 2025 Q1 | B11: 20 | C11: 超预期增长 (开年消费强劲) | J11: Transform | K11: Zero removed; numeric-like text parsed for analytics
A12: 2024 Q4 | B12: 15 | C12: 稳步好于预期 (就业市场韧性) | J12: 稳步好于预期 (就业市场韧性) | K12: 15
A13: 2024 Q3 | B13: -15 | C13: 不及预期 (高利率对消费的滞后打击) | J13: 不及预期 (高利率对消费的滞后打击) | K13: -15
A14: 2024 Q2 | B14: -20 | C14: 明显不及预期 (二季度宏观数据集体走弱) | J14: 明显不及预期 (二季度宏观数据集体走弱) | K14: -20
A15: 2024 Q1 | B15: 25 | C15: 好于预期 (通胀降温速度快于预期) | J15: 好于预期 (通胀降温速度快于预期) | K15: 25
A16: 2023 Q4 | B16: 10 | C16: 小幅好于预期 (假日零售季表现平稳) | J16: 小幅好于预期 (假日零售季表现平稳) | K16: 10
A17: 2023 Q3 | B17: 60 | C17: 大幅超预期 (美国经济表现出惊人韧性) | J17: 大幅超预期 (美国经济表现出惊人韧性) | K17: 60
A18: 2023 Q2 | B18: 30 | C18: 好于预期 (衰退预言再次落空) | J18: 好于预期 (衰退预言再次落空) | K18: 30
A19: 2023 Q1 | B19: 40 | C19: 好于预期 (一月非农数据引发的巨震) | J19: 好于预期 (一月非农数据引发的巨震) | K19: 40
A20: 2022 Q4 | B20: -10 | C20: 小幅不及预期 (加息压力显现) | J20: 小幅不及预期 (加息压力显现) | K20: -10
A21: 2022 Q3 | B21: 20 | C21: 好于预期 (企业支出保持稳健) | J21: 好于预期 (企业支出保持稳健) | K21: 20
A22: 2022 Q2 | B22: -40 | C22: 明显不及预期 (通胀爆表及经济增长放缓) | J22: 明显不及预期 (通胀爆表及经济增长放缓) | K22: -40
A23: 2022 Q1 | B23: 10 | C23: 小幅好于预期 (奥密克戎疫情后复苏) | J23: 小幅好于预期 (奥密克戎疫情后复苏) | K23: 10
... A27: 2021 Q1 | B27: 40 | C27: 好于预期 (新一轮财政刺激落地) | J27: 好于预期 (新一轮财政刺激落地) | K27: 40

Sheet S10_主权基金净流入情况
A1: 主权基金净流入情况
A3: Category | B3: Sentiment | C3: Primary Metric | D3: 净流入估算 (Est. Net Inflow) | E3: Frequency | F3: Quarterly | H3: Back to Dashboard
A4: Orientation | B4: HigherBetter | C4: Latest | D4: 50.2 | E4: Previous | F4: 55.6
A7: 季度 (Quarter) | B7: 净流入估算 (Est. Net Inflow) | C7: 主要资金来源 / 动向 | D7: 数据参考源 | J7: TimePoint | K7: Series
A8: 2025 Q4 | B8: 42.5 | C8: 中东基金（PIF, ADIA）加大 AI 与半导体配置 | D8: Global SWF | J8: Global SWF | K8: 42.5
A9: 2025 Q3 | B9: 38.2 | C9: 挪威 NBIM 增持科技股；新加坡 GIC 保持稳定 | D9: SWFI | J9: SWFI | K9: 38.2
A10: 2025 Q2 | B10: 45 | C10: 资本重组需求下的美股成长股增持 | D10: IFSWF | J10: Data Source | K10: Uploaded file: 基础数据v2.xlsx
A11: 2025 Q1 | B11: 48.8 | C11: 开年全球主权基金重新平衡权重 (Rebalancing) | D11: Global SWF | J11: Transform | K11: Zero removed; numeric-like text parsed for analytics
A12: 2024 Q4 | B12: 35.5 | C12: 大选后波动率下降，资金回流大盘股 | D12: SWFI | J12: 大选后波动率下降，资金回流大盘股-SWFI | K12: 35.5
A13: 2024 Q3 | B13: 28 | C13: 避险情绪升温，流入速度放缓 | D13: Global SWF | J13: 避险情绪升温，流入速度放缓-Global SWF | K13: 28
A14: 2024 Q2 | B14: 31.2 | C14: 加大对数据中心相关房地产及基础设施证券化投资 | D14: IFSWF | J14: IFSWF | K14: 31.2
A15: 2024 Q1 | B15: 39.5 | C15: 追逐“美股卓越七巨头” (Mag 7) 浪潮 | D15: SWFI | J15: SWFI | K15: 39.5
A16: 2023 Q4 | B16: 22.4 | C16: 利率见顶预期明确，主权基金从债市回流股市 | D16: Global SWF | J16: 利率见顶预期明确，主权基金从债市回流股市-Global SWF | K16: 22.4
A17: 2023 Q3 | B17: 15.8 | C17: 低点：受高利率打击，对美股持谨慎态度 | D17: SWFI | J17: 低点：受高利率打击，对美股持谨慎态度-SWFI | K17: 15.8
A18: 2023 Q2 | B18: 26.7 | C18: 沙特 PIF 逆势加仓美股科技及游戏板块 | D18: Global SWF | J18: 沙特 PIF 逆势加仓美股科技及游戏板块-Global SWF | K18: 26.7
A19: 2023 Q1 | B19: 18.5 | C19: 银行危机期间的战术性回避 | D19: IFSWF | J19: 银行危机期间的战术性回避-IFSWF | K19: 18.5
A20: 2022 Q4 | B20: 33 | C20: 趁低估值进行“底部钓鱼” (Bottom Fishing) | D20: SWFI | J20: SWFI | K20: 33
A21: 2022 Q3 | B21: 12.5 | C21: 极低点：美联储连续加息 75BP，资金回笼现金 | D21: Global SWF | J21: Global SWF | K21: 12.5
A22: 2022 Q2 | B22: 19.8 | C22: 能源价格暴涨，海湾国家基金流动性极其充沛 | D22: IFSWF | J22: 能源价格暴涨，海湾国家基金流动性极其充沛-IFSWF | K22: 19.8
A23: 2022 Q1 | B23: 24.2 | C23: 俄乌冲突初期引发的全球资产配置重新审视 | D23: SWFI | J23: 俄乌冲突初期引发的全球资产配置重新审视-SWFI | K23: 24.2
... A27: 2021 Q1 | B27: 50.2 | C27: 对拜登政府财政刺激计划的信心投票 | D27: IFSWF | J27: 对拜登政府财政刺激计划的信心投票-IFSWF | K27: 50.2

Sheet S11_标普500的现金流 PEG
A1: 标普500的现金流 PEG
A3: Category | B3: Valuation | C3: Primary Metric | D3: 现金流 PEG | E3: Frequency | F3: Quarterly | H3: Back to Dashboard
A4: Orientation | B4: HigherWorse | C4: Latest | D4: 1.09 | E4: Previous | F4: 1.03
A7: 季度 (Quarter) | B7: 平均 P/CF (倍) | C7: 预期现金流增长率 (%) | D7: 现金流 PEG | E7: 估值评判 | J7: TimePoint | K7: Series
A8: 2025 Q4 | B8: 16.8 | C8: 0.112 | D8: 1.5 | E8: 偏高 | J8: 偏高 | K8: 1.5
A9: 2025 Q3 | B9: 16.5 | C9: 0.108 | D9: 1.53 | E9: 偏高 | J9: 偏高 | K9: 1.53
A10: 2025 Q2 | B10: 15.9 | C10: 0.105 | D10: 1.51 | E10: 偏高 | J10: Data Source | K10: Uploaded file: 基础数据v2.xlsx
A11: 2025 Q1 | B11: 15.2 | C11: 0.102 | D11: 1.49 | E11: 中性偏高 | J11: Transform | K11: Zero removed; numeric-like text parsed for analytics
A12: 2024 Q4 | B12: 14.8 | C12: 0.104 | D12: 1.42 | E12: 中性 | J12: 中性 | K12: 1.42
A13: 2024 Q3 | B13: 14.2 | C13: 0.098 | D13: 1.45 | E13: 中性 | J13: 中性 | K13: 1.45
A14: 2024 Q2 | B14: 13.8 | C14: 0.095 | D14: 1.45 | E14: 中性 | J14: 中性 | K14: 1.45
A15: 2024 Q1 | B15: 13.5 | C15: 0.092 | D15: 1.47 | E15: 中性 | J15: 中性 | K15: 1.47
A16: 2023 Q4 | B16: 12.8 | C16: 0.088 | D16: 1.45 | E16: 中性 | J16: 中性 | K16: 1.45
A17: 2023 Q3 | B17: 12.2 | C17: 0.085 | D17: 1.44 | E17: 中性 | J17: 中性 | K17: 1.44
A18: 2023 Q2 | B18: 12.5 | C18: 0.082 | D18: 1.52 | E18: 略高 | J18: 略高 | K18: 1.52
A19: 2023 Q1 | B19: 11.8 | C19: 0.075 | D19: 1.57 | E19: 偏高 (增长预期低迷) | J19: 偏高 (增长预期低迷) | K19: 1.57
A20: 2022 Q4 | B20: 11.2 | C20: 0.078 | D20: 1.44 | E20: 中性 | J20: 中性 | K20: 1.44
A21: 2022 Q3 | B21: 10.8 | C21: 0.082 | D21: 1.32 | E21: 低估 (性价比极高) | J21: 低估 (性价比极高) | K21: 1.32
A22: 2022 Q2 | B22: 11.5 | C22: 0.085 | D22: 1.35 | E22: 较低 | J22: 较低 | K22: 1.35
A23: 2022 Q1 | B23: 13.2 | C23: 0.09 | D23: 1.47 | E23: 中性 | J23: 中性 | K23: 1.47
... A27: 2021 Q1 | B27: 15.8 | C27: 0.145 | D27: 1.09 | E27: 极度低估 | J27: 极度低估 | K27: 1.09

Sheet S12_标普500的真实股东收益率（Total Shareho
A1: 标普500的真实股东收益率（Total Shareholder
A3: Category | B3: Valuation | C3: Primary Metric | D3: TSY (A+B) | E3: Frequency | F3: Quarterly | H3: Back to Dashboard
A4: Orientation | B4: HigherBetter | C4: Latest | D4: 0.0398 | E4: Previous | F4: 0.0447
A7: 季度 (Quarter) | B7: 股息收益率 (%) | C7: 净回购收益率 (%) | D7: TSY (A+B) | E7: 10Y 国债 (%) | F7: 利差 (TSY - 10Y) | J7: TimePoint | K7: Series
A8: 2025 Q4 | B8: 0.0125 | C8: 0.0185 | D8: 0.031 | E8: 0.042 | F8: -0.011 | J8: 1 | K8: 0.031
A9: 2025 Q3 | B9: 0.0128 | C9: 0.019 | D9: 0.0318 | E9: 0.044 | F9: -0.0122 | J9: 2 | K9: 0.0318
A10: 2025 Q2 | B10: 0.0135 | C10: 0.0195 | D10: 0.033 | E10: 0.043 | F10: -0.01 | J10: Data Source | K10: Uploaded file: 基础数据v2.xlsx
A11: 2025 Q1 | B11: 0.0138 | C11: 0.021 | D11: 0.0348 | E11: 0.041 | F11: -0.0062 | J11: Transform | K11: Zero removed; numeric-like text parsed for analytics
A12: 2024 Q4 | B12: 0.0142 | C12: 0.0215 | D12: 0.0357 | E12: 0.039 | F12: -0.0033 | J12: 5 | K12: 0.0357
A13: 2024 Q3 | B13: 0.0145 | C13: 0.0185 | D13: 0.033 | E13: 0.04 | F13: -0.007 | J13: 6 | K13: 0.033
A14: 2024 Q2 | B14: 0.0148 | C14: 0.017 | D14: 0.0318 | E14: 0.045 | F14: -0.0132 | J14: 7 | K14: 0.0318
A15: 2024 Q1 | B15: 0.015 | C15: 0.0165 | D15: 0.0315 | E15: 0.043 | F15: -0.0115 | J15: 8 | K15: 0.0315
A16: 2023 Q4 | B16: 0.0155 | C16: 0.016 | D16: 0.0315 | E16: 0.041 | F16: -0.0095 | J16: 9 | K16: 0.0315
A17: 2023 Q3 | B17: 0.0162 | C17: 0.0145 | D17: 0.0307 | E17: 0.046 | F17: -0.0153 | J17: 10 | K17: 0.0307
A18: 2023 Q2 | B18: 0.0158 | C18: 0.018 | D18: 0.0338 | E18: 0.038 | F18: -0.0042 | J18: 11 | K18: 0.0338
A19: 2023 Q1 | B19: 0.0165 | C19: 0.022 | D19: 0.0385 | E19: 0.035 | F19: 0.0035 | J19: 12 | K19: 0.0385
A20: 2022 Q4 | B20: 0.0172 | C20: 0.025 | D20: 0.0422 | E20: 0.039 | F20: 0.0032 | J20: 13 | K20: 0.0422
A21: 2022 Q3 | B21: 0.0185 | C21: 0.028 | D21: 0.0465 | E21: 0.038 | F21: 0.0085 | J21: 14 | K21: 0.0465
A22: 2022 Q2 | B22: 0.0168 | C22: 0.032 | D22: 0.0488 | E22: 0.03 | F22: 0.0188 | J22: 15 | K22: 0.0488
A23: 2022 Q1 | B23: 0.0145 | C23: 0.035 | D23: 0.0495 | E23: 0.023 | F23: 0.0265 | J23: 16 | K23: 0.0495
... A27: 2021 Q1 | B27: 0.0148 | C27: 0.025 | D27: 0.0398 | E27: 0.017 | F27: 0.0228 | J27: 20 | K27: 0.0398

Sheet S13_AAII个人投资者净看多比例
A1: AAII个人投资者净看多比例
A3: Category | B3: Sentiment | C3: Primary Metric | D3: 净看多比例 (%) | E3: Frequency | F3: Quarterly | H3: Back to Dashboard
A4: Orientation | B4: HigherWorse | C4: Latest | D4: 0.257 | E4: Previous | F4: 0.297
A7: 季度 (Quarter) | B7: 看多比例 (%) | C7: 看空比例 (%) | D7: 净看多比例 (%) | E7: 市场情绪评价 | J7: TimePoint | K7: Series
A8: 2025 Q4 | B8: 0.485 | C8: 0.221 | D8: 0.264 | E8: 极度乐观 (贪婪) | J8: 极度乐观 (贪婪) | K8: 0.264
A9: 2025 Q3 | B9: 0.422 | C9: 0.258 | D9: 0.164 | E9: 乐观 | J9: 乐观 | K9: 0.164
A10: 2025 Q2 | B10: 0.445 | C10: 0.242 | D10: 0.203 | E10: 极度乐观 | J10: Data Source | K10: Uploaded file: 基础数据v2.xlsx
A11: 2025 Q1 | B11: 0.468 | C11: 0.215 | D11: 0.253 | E11: 极度乐观 | J11: Transform | K11: Zero removed; numeric-like text parsed for analytics
A12: 2024 Q4 | B12: 0.452 | C12: 0.235 | D12: 0.217 | E12: 极度乐观 | J12: 极度乐观 | K12: 0.217
A13: 2024 Q3 | B13: 0.395 | C13: 0.282 | D13: 0.113 | E13: 乐观 | J13: 乐观 | K13: 0.113
A14: 2024 Q2 | B14: 0.382 | C14: 0.305 | D14: 0.077 | E14: 中性偏乐观 | J14: 中性偏乐观 | K14: 0.077
A15: 2024 Q1 | B15: 0.441 | C15: 0.248 | D15: 0.193 | E15: 乐观 | J15: 乐观 | K15: 0.193
A16: 2023 Q4 | B16: 0.415 | C16: 0.262 | D16: 0.153 | E16: 乐观 | J16: 乐观 | K16: 0.153
A17: 2023 Q3 | B17: 0.368 | C17: 0.325 | D17: 0.043 | E17: 中性 | J17: 中性 | K17: 0.043
A18: 2023 Q2 | B18: 0.324 | C18: 0.358 | D18: -0.034 | E18: 忧虑 | J18: 忧虑 | K18: -0.034
A19: 2023 Q1 | B19: 0.245 | C19: 0.422 | D19: -0.177 | E19: 显著悲观 | J19: 显著悲观 | K19: -0.177
A20: 2022 Q4 | B20: 0.228 | C20: 0.485 | D20: -0.257 | E20: 极度悲观 (恐慌) | J20: 极度悲观 (恐慌) | K20: -0.257
A21: 2022 Q3 | B21: 0.215 | C21: 0.522 | D21: -0.307 | E21: 极度悲观 (底部区) | J21: 极度悲观 (底部区) | K21: -0.307
A22: 2022 Q2 | B22: 0.202 | C22: 0.545 | D22: -0.343 | E22: 极度悲观 (恐慌) | J22: 极度悲观 (恐慌) | K22: -0.343
A23: 2022 Q1 | B23: 0.254 | C23: 0.408 | D23: -0.154 | E23: 悲观 | J23: 悲观 | K23: -0.154
... A27: 2021 Q1 | B27: 0.482 | C27: 0.225 | D27: 0.257 | E27: 极度贪婪 | J27: 极度贪婪 | K27: 0.257

Sheet S14_Market Vane 股市看涨情绪
A1: Market Vane 股市看涨情绪
A3: Category | B3: Sentiment | C3: Primary Metric | D3: 看涨共识指数 (%) | E3: Frequency | F3: Quarterly | H3: Back to Dashboard
A4: Orientation | B4: HigherWorse | C4: Latest | D4: 0.75 | E4: Previous | F4: 0.78
A7: 季度 (Quarter) | B7: 看涨共识指数 (%) | C7: 情绪水位 (Sentiment Level) | D7: 市场背景提示 | J7: TimePoint | K7: Series
A8: 2025 Q4 | B8: 0.68 | C8: 偏高 (贪婪) | D8: 市场定价 AI 商业化全面落地 | J8: 偏高 (贪婪)-市场定价 AI 商业化全面落地 | K8: 0.68
A9: 2025 Q3 | B9: 0.64 | C9: 乐观 | D9: 降息预期后的震荡上行 | J9: 乐观-降息预期后的震荡上行 | K9: 0.64
A10: 2025 Q2 | B10: 0.72 | C10: 极度乐观 (警戒) | D10: 标普 500 突破关键整数关口 | J10: Data Source | K10: Uploaded file: 基础数据v2.xlsx
A11: 2025 Q1 | B11: 0.69 | C11: 偏高 | D11: 机构资金持续流入大盘股 | J11: Transform | K11: Zero removed; numeric-like text parsed for analytics
A12: 2024 Q4 | B12: 0.65 | C12: 乐观 | D12: 软着陆预期成为市场共识 | J12: 乐观-软着陆预期成为市场共识 | K12: 0.65
A13: 2024 Q3 | B13: 0.58 | C13: 中性偏乐观 | D13: 季末出现获利回吐压力 | J13: 中性偏乐观-季末出现获利回吐压力 | K13: 0.58
A14: 2024 Q2 | B14: 0.61 | C14: 乐观 | D14: 财报季表现稳健支撑情绪 | J14: 乐观-财报季表现稳健支撑情绪 | K14: 0.61
A15: 2024 Q1 | B15: 0.67 | C15: 偏高 | D15: AI 硬件股（NVDA等）暴涨引发 | J15: 偏高-AI 硬件股（NVDA等）暴涨引发 | K15: 0.67
A16: 2023 Q4 | B16: 0.55 | C16: 中性 | D16: 利率转向讨论开始升温 | J16: 中性-利率转向讨论开始升温 | K16: 0.55
A17: 2023 Q3 | B17: 0.48 | C17: 中性偏悲观 | D17: 重要低点：对“Higher for Longer”的恐惧 | J17: 中性偏悲观 | K17: 0.48
A18: 2023 Q2 | B18: 0.52 | C18: 中性 | D18: 银行业压力后的情绪修复 | J18: 中性-银行业压力后的情绪修复 | K18: 0.52
A19: 2023 Q1 | B19: 0.45 | C19: 悲观 | D19: 硅谷银行事件引发系统性担忧 | J19: 悲观-硅谷银行事件引发系统性担忧 | K19: 0.45
A20: 2022 Q4 | B20: 0.42 | C20: 极度悲观 | D20: 通胀数据居高不下后的绝望期 | J20: 极度悲观-通胀数据居高不下后的绝望期 | K20: 0.42
A21: 2022 Q3 | B21: 0.38 | C21: 极度悲观 (底部区) | D21: 5年最低点：加息缩表双重重压 | J21: 极度悲观 (底部区)-5年最低点：加息缩表双重重压 | K21: 0.38
A22: 2022 Q2 | B22: 0.41 | C22: 极度悲观 | D22: 市场进入技术性熊市确认期 | J22: 极度悲观-市场进入技术性熊市确认期 | K22: 0.41
A23: 2022 Q1 | B23: 0.54 | C23: 中性 | D23: 俄乌冲突爆发后的初次冲击 | J23: 中性-俄乌冲突爆发后的初次冲击 | K23: 0.54
... A27: 2021 Q1 | B27: 0.75 | C27: 极度乐观 | D27: 经济全面重启的强劲预期 | J27: 极度乐观-经济全面重启的强劲预期 | K27: 0.75

Sheet S15_保证金债务和市值比率
A1: 保证金债务和市值比率
A3: Category | B3: Sentiment | C3: Primary Metric | D3: 净看多比例 (%) | E3: Frequency | F3: Quarterly | H3: Back to Dashboard
A4: Orientation | B4: HigherWorse | C4: Latest | D4: 0.257 | E4: Previous | F4: 0.297
A7: 季度 (Quarter) | B7: 看多比例 (%) | C7: 看空比例 (%) | D7: 净看多比例 (%) | E7: 市场情绪评价 | J7: TimePoint | K7: Series
A8: 2025 Q4 | B8: 0.485 | C8: 0.221 | D8: 0.264 | E8: 极度乐观 (贪婪) | J8: 极度乐观 (贪婪) | K8: 0.264
A9: 2025 Q3 | B9: 0.422 | C9: 0.258 | D9: 0.164 | E9: 乐观 | J9: 乐观 | K9: 0.164
A10: 2025 Q2 | B10: 0.445 | C10: 0.242 | D10: 0.203 | E10: 极度乐观 | J10: Data Source | K10: Uploaded file: 基础数据v2.xlsx
A11: 2025 Q1 | B11: 0.468 | C11: 0.215 | D11: 0.253 | E11: 极度乐观 | J11: Transform | K11: Zero removed; numeric-like text parsed for analytics
A12: 2024 Q4 | B12: 0.452 | C12: 0.235 | D12: 0.217 | E12: 极度乐观 | J12: 极度乐观 | K12: 0.217
A13: 2024 Q3 | B13: 0.395 | C13: 0.282 | D13: 0.113 | E13: 乐观 | J13: 乐观 | K13: 0.113
A14: 2024 Q2 | B14: 0.382 | C14: 0.305 | D14: 0.077 | E14: 中性偏乐观 | J14: 中性偏乐观 | K14: 0.077
A15: 2024 Q1 | B15: 0.441 | C15: 0.248 | D15: 0.193 | E15: 乐观 | J15: 乐观 | K15: 0.193
A16: 2023 Q4 | B16: 0.415 | C16: 0.262 | D16: 0.153 | E16: 乐观 | J16: 乐观 | K16: 0.153
A17: 2023 Q3 | B17: 0.368 | C17: 0.325 | D17: 0.043 | E17: 中性 | J17: 中性 | K17: 0.043
A18: 2023 Q2 | B18: 0.324 | C18: 0.358 | D18: -0.034 | E18: 忧虑 | J18: 忧虑 | K18: -0.034
A19: 2023 Q1 | B19: 0.245 | C19: 0.422 | D19: -0.177 | E19: 显著悲观 | J19: 显著悲观 | K19: -0.177
A20: 2022 Q4 | B20: 0.228 | C20: 0.485 | D20: -0.257 | E20: 极度悲观 (恐慌) | J20: 极度悲观 (恐慌) | K20: -0.257
A21: 2022 Q3 | B21: 0.215 | C21: 0.522 | D21: -0.307 | E21: 极度悲观 (底部区) | J21: 极度悲观 (底部区) | K21: -0.307
A22: 2022 Q2 | B22: 0.202 | C22: 0.545 | D22: -0.343 | E22: 极度悲观 (恐慌) | J22: 极度悲观 (恐慌) | K22: -0.343
A23: 2022 Q1 | B23: 0.254 | C23: 0.408 | D23: -0.154 | E23: 悲观 | J23: 悲观 | K23: -0.154
... A27: 2021 Q1 | B27: 0.482 | C27: 0.225 | D27: 0.257 | E27: 极度贪婪 | J27: 极度贪婪 | K27: 0.257

Sheet S16_TGA账户余额
A1: TGA账户余额
A3: Category | B3: Liquidity | C3: Primary Metric | D3: TGA账户余额 | E3: Frequency | F3: Quarterly | H3: Back to Dashboard
A4: Orientation | B4: HigherWorse | C4: Latest | D4: 871 | E4: Previous | F4: 820
A7: 年份 | B7: 第一季度 (Q1) | C7: 第二季度 (Q2) | D7: 第三季度 (Q3) | E7: 第四季度 (Q4) | J7: TimePoint | K7: Series
A8: 2021 | B8: 1122 | C8: 852 | D8: 215 | E8: 406 | J8: 2021-第一季度 (Q1) | K8: 1122
A9: 2022 | B9: 628 | C9: 757 | D9: 636 | E9: 447 | J9: 2021-第二季度 (Q2) | K9: 852
A10: 2023 | B10: 178 | C10: 402 | D10: 661 | E10: 769 | J10: Data Source | K10: Uploaded file: 基础数据v2.xlsx
A11: 2024 | B11: 745 | C11: 755 | D11: 818 | E11: 702 | J11: Transform | K11: Zero removed; numeric-like text parsed for analytics
A12: 2025 | B12: $325* | C12: 650 | D12: 835 | E12: 820 | J12: 2022-第一季度 (Q1) | K12: 628
A13: 2026 | B13: $871 (最新) | C13: - | D13: - | E13: - | J13: 2022-第二季度 (Q2) | K13: 757
J14: 2022-第三季度 (Q3) | K14: 636
J15: 2022-第四季度 (Q4) | K15: 447
J16: 2023-第一季度 (Q1) | K16: 178
J17: 2023-第二季度 (Q2) | K17: 402
J18: 2023-第三季度 (Q3) | K18: 661
J19: 2023-第四季度 (Q4) | K19: 769
J20: 2024-第一季度 (Q1) | K20: 745
J21: 2024-第二季度 (Q2) | K21: 755
J22: 2024-第三季度 (Q3) | K22: 818
J23: 2024-第四季度 (Q4) | K23: 702
J24: 2025-第一季度 (Q1) | K24: 325
J25: 2025-第二季度 (Q2) | K25: 650
... J28: 2026-第一季度 (Q1) | K28: 871

Sheet S17_SOFR-OIS 基差
A1: SOFR-OIS 基差
A3: Category | B3: Liquidity | C3: Primary Metric | D3: 代表性周值 (bps) | E3: Frequency | F3: Mixed | H3: Back to Dashboard
A4: Orientation | B4: HigherWorse | C4: Latest | D4: 18 | E4: Previous | F4: 16
A7: 时间段 | B7: 主要分布区间 (bps) | C7: 代表性周值 (bps) | D7: 关键事件与市场背景 | J7: TimePoint | K7: Series
A8: 2021年 (Q1-Q4) | B8: -10 至 -2 | C8: -6 | D8: 流动性泛滥：回购利率跌至 0，TGA 资金大量投放，利差一度深度倒挂。 | J8: 1 | K8: -6
A9: 2022年 (Q1-Q4) | B9: -2 至 +3 | C9: 1 | D9: 美联储加息周期开启：QT 开始，流动性溢价回归正值，波动逐渐增加。 | J9: 2 | K9: 1
A10: 2023年 (Q1-Q2) | B10: -5 至 +10 | C10: 8 | D10: 银行业动荡 (SVB)：市场对担保融资需求增加，利差显著走宽。 | J10: Data Source | K10: Uploaded file: 基础数据v2.xlsx
A11: 2023年 (Q3-Q4) | B11: +2 至 +12 | C11: 11 | D11: 债务上限解决后大量发债：财政部回补 TGA，私人部门融资成本上升。 | J11: Transform | K11: Zero removed; numeric-like text parsed for analytics
A12: 2024年 (Q1-Q2) | B12: 0 至 +8 | C12: 4 | D12: 中性期：逆回购（ON RRP）规模下降，流动性由极度充裕转为均衡。 | J12: 5 | K12: 4
A13: 2024年 (Q3-Q4) | B13: +3 至 +15 | C13: 12 | D13: 波动加剧：季末、年末效应明显，回购利率因短期国债供应量大而上行。 | J13: 6 | K13: 12
A14: 2025年 (Q1-Q2) | B14: -1 至 +7 | C14: 3 | D14: 预期降息：美联储政策转向预期升温，融资市场相对平稳。 | J14: 7 | K14: 3
A15: 2025年 (Q3-Q4) | B15: +5 至 +18 | C15: 14 | D15: 流动性摩擦：准备金余额下降至关键阈值，回购市场资金紧张加剧。 | J15: 8 | K15: 14
A16: 2026年 1 月 | B16: +8 至 +20 | C16: 16 | D16: 紧缩尾声效应：流动性分布不均，利差在季末节点大幅跳升。 | J16: 9 | K16: 16
A17: 2026年 2 月至今 | B17: +10 至 +22 | C17: 18 | D17: 当前水平：近期回购市场压力持续，基差维持在多年高位。 | J17: 10 | K17: 18

Sheet S18_CARRY TO RISK RITIO
A1: CARRY TO RISK RITIO
A3: Category | B3: Liquidity | C3: Primary Metric | D3: CARRY TO RISK RITIO | E3: Frequency | F3: Quarterly | H3: Back to Dashboard
A4: Orientation | B4: HigherBetter | C4: Latest | D4: 0.12 | E4: Previous | F4: 0.15
A7: 年份 | B7: 第一季度 (Q1) | C7: 第二季度 (Q2) | D7: 第三季度 (Q3) | E7: 第四季度 (Q4) | F7: 市场环境背景 | J7: TimePoint | K7: Series
A8: 2021 | B8: 0.04 | C8: 0.05 | D8: 0.04 | E8: 0.06 | F8: 低息差、低波动环境，套利空间极小。 | J8: 2021-低息差、低波动环境，套利空间极小。-第一季度 (Q1) | K8: 0.04
A9: 2022 | B9: 0.08 | C9: 0.22 | D9: 0.28 | E9: 0.25 | F9: 美联储猛烈加息，利差走阔，CTR 快速爬升。 | J9: 2021-低息差、低波动环境，套利空间极小。-第二季度 (Q2) | K9: 0.05
A10: 2023 | B10: 0.35 | C10: 0.42 | D10: 0.48 | E10: 0.4 | F10: 套利黄金期：利差封顶但波动受限，CTR 触及高位。 | J10: Data Source | K10: Uploaded file: 基础数据v2.xlsx
A11: 2024 | B11: 0.45 | C11: 0.43 | D11: 0.32 | E11: 0.35 | F11: 日元干预风险增加，隐含波动率上升导致 CTR 回落。 | J11: Transform | K11: Zero removed; numeric-like text parsed for analytics
A12: 2025 | B12: 0.28 | C12: 0.25 | D12: 0.18 | E12: 0.15 | F12: 日本央行加息预期+美联储降息，利差收窄。 | J12: 2022-第一季度 (Q1) | K12: 0.08
A13: 2026 | B13: 0.12 | C13: - | D13: - | E13: - | F13: 当前：利差进一步收缩，日元波动率高企。 | J13: 2022-第二季度 (Q2) | K13: 0.22
J14: 2022-第三季度 (Q3) | K14: 0.28
J15: 2022-第四季度 (Q4) | K15: 0.25
J16: 2023-第一季度 (Q1) | K16: 0.35
J17: 2023-第二季度 (Q2) | K17: 0.42
J18: 2023-第三季度 (Q3) | K18: 0.48
J19: 2023-第四季度 (Q4) | K19: 0.4
J20: 2024-第一季度 (Q1) | K20: 0.45
J21: 2024-第二季度 (Q2) | K21: 0.43
J22: 2024-第三季度 (Q3) | K22: 0.32
J23: 2024-第四季度 (Q4) | K23: 0.35
J24: 2025-日本央行加息预期+美联储降息，利差收窄。-第一季度 (Q1) | K24: 0.28
J25: 2025-日本央行加息预期+美联储降息，利差收窄。-第二季度 (Q2) | K25: 0.25
... J28: 2026-当前：利差进一步收缩，日元波动率高企。-第一季度 (Q1) | K28: 0.12

Sheet S19_高盛美国宏观金融指数
A1: 高盛美国宏观金融指数
A3: Category | B3: Valuation | C3: Primary Metric | D3: 高盛美国宏观金融指数 | E3: Frequency | F3: Quarterly | H3: Back to Dashboard
A4: Orientation | B4: LowerBetter | C4: Latest | D4: 97.6 | E4: Previous | F4: 97.8
A7: 年份 | B7: 第一季度 (Q1) | C7: 第二季度 (Q2) | D7: 第三季度 (Q3) | E7: 第四季度 (Q4) | F7: 宏观环境逻辑 | J7: TimePoint | K7: Series
A8: 2021 | B8: 97.2 | C8: 97 | D8: 97.1 | E8: 97.4 | F8: 历史最松水平：极低利率与股市繁荣，对经济增长提供极大支撑。 | J8: 2021-第一季度 (Q1) | K8: 97.2
A9: 2022 | B9: 98.5 | C9: 99.8 | D9: 100.1 | E9: 100.3 | F9: 剧烈收紧：美联储暴力加息，标普500进入熊市，FCI 迅速回升至 100 以上。 | J9: 2021-第二季度 (Q2) | K9: 97
A10: 2023 | B10: 99.9 | C10: 100.2 | D10: 100.5 | E10: 99.4 | F10: 先紧后松：Q4 随着通胀数据超预期下行，市场提前交易降息，FCI 大幅松动。 | J10: Data Source | K10: Uploaded file: 基础数据v2.xlsx
A11: 2024 | B11: 98.8 | C11: 99.2 | D11: 99 | E11: 98.5 | F11: 稳步改善：虽然利率仍高，但信贷利差收窄和 AI 驱动的股市反弹抵消了高利率。 | J11: Transform | K11: Zero removed; numeric-like text parsed for analytics
A12: 2025 | B12: 99.1 | C12: 98.4 | D12: 98 | E12: 97.8 | F12: 加速转向：美联储降息周期兑现，税收预期及财政刺激预期进一步改善了金融环境。 | J12: 2022-第一季度 (Q1) | K12: 98.5
A13: 2026 | B13: 97.6 | C13: - | D13: - | E13: - | F13: 当前：进入“容易（Easier）”区间，高盛预计 2026 年金融条件将持续对增长有利。 | J13: 2022-第二季度 (Q2) | K13: 99.8
J14: 2022-第三季度 (Q3) | K14: 100.1
J15: 2022-第四季度 (Q4) | K15: 100.3
J16: 2023-第一季度 (Q1) | K16: 99.9
J17: 2023-第二季度 (Q2) | K17: 100.2
J18: 2023-第三季度 (Q3) | K18: 100.5
J19: 2023-第四季度 (Q4) | K19: 99.4
J20: 2024-第一季度 (Q1) | K20: 98.8
J21: 2024-第二季度 (Q2) | K21: 99.2
J22: 2024-第三季度 (Q3) | K22: 99
J23: 2024-第四季度 (Q4) | K23: 98.5
J24: 2025-第一季度 (Q1) | K24: 99.1
J25: 2025-第二季度 (Q2) | K25: 98.4
... J28: 2026-第一季度 (Q1) | K28: 97.6

Sheet S20_彭博美国金融条件指数
A1: 彭博美国金融条件指数
A3: Category | B3: Liquidity | C3: Primary Metric | D3: 彭博美国金融条件指数 | E3: Frequency | F3: Quarterly | H3: Back to Dashboard
A4: Orientation | B4: HigherBetter | C4: Latest | D4: 0.85 | E4: Previous | F4: 1.02
A7: 年份 | B7: 第一季度 (Q1) | C7: 第二季度 (Q2) | D7: 第三季度 (Q3) | E7: 第四季度 (Q4) | F7: 核心驱动因素 | J7: TimePoint | K7: Series
A8: 2021 | B8: 1.25 | C8: 1.38 | D8: 1.42 | E8: 1.15 | F8: 流动性顶峰：超低利率与强劲股市带动 Z-Score 处于极高水平。 | J8: 2021-第一季度 (Q1) | K8: 1.25
A9: 2022 | B9: 0.45 | C9: -0.65 | D9: -0.88 | E9: -1.12 | F9: 快速入冬：加息开启，股市与债市双杀，指数跌入负值（紧张）。 | J9: 2021-第二季度 (Q2) | K9: 1.38
A10: 2023 | B10: -0.92 | C10: -0.45 | D10: -0.32 | E10: 0.25 | F10: 修复期：Q4 随着通胀放缓，市场预期转鸽，指数重回正值区间。 | J10: Data Source | K10: Uploaded file: 基础数据v2.xlsx
A11: 2024 | B11: 0.48 | C11: 0.35 | D11: 0.55 | E11: 0.72 | F11: 均衡宽松：信贷利差收窄，股市创下新高，条件持续改善。 | J11: Transform | K11: Zero removed; numeric-like text parsed for analytics
A12: 2025 | B12: 0.65 | C12: 0.82 | D12: 0.95 | E12: 1.02 | F12: 政策驱动：美联储降息周期启动，标普500上涨，支撑了宽松环境。 | J12: 2022-第一季度 (Q1) | K12: 0.45
A13: 2026 | B13: 0.85 | C13: - | D13: - | E13: - | F13: 当前：虽有地缘波动，但仍处于历史偏松区间。 | J13: 2022-第二季度 (Q2) | K13: -0.65
J14: 2022-第三季度 (Q3) | K14: -0.88
J15: 2022-第四季度 (Q4) | K15: -1.12
J16: 2023-第一季度 (Q1) | K16: -0.92
J17: 2023-第二季度 (Q2) | K17: -0.45
J18: 2023-第三季度 (Q3) | K18: -0.32
J19: 2023-第四季度 (Q4) | K19: 0.25
J20: 2024-第一季度 (Q1) | K20: 0.48
J21: 2024-第二季度 (Q2) | K21: 0.35
J22: 2024-第三季度 (Q3) | K22: 0.55
J23: 2024-第四季度 (Q4) | K23: 0.72
J24: 2025-第一季度 (Q1) | K24: 0.65
J25: 2025-第二季度 (Q2) | K25: 0.82
... J28: 2026-第一季度 (Q1) | K28: 0.85

Sheet S21_芝加哥联储全国金融条件指数 (NFCI)
A1: 芝加哥联储全国金融条件指数 (NFCI)
A3: Category | B3: Liquidity | C3: Primary Metric | D3: 芝加哥联储全国金融条件指数 (NFCI) | E3: Frequency | F3: Quarterly | H3: Back to Dashboard
A4: Orientation | B4: LowerBetter | C4: Latest | D4: -0.48 | E4: Previous | F4: -0.36
A7: 年份 | B7: 第一季度 (Q1) | C7: 第二季度 (Q2) | D7: 第三季度 (Q3) | E7: 第四季度 (Q4) | F7: 宏观环境说明 | J7: TimePoint | K7: Series
A8: 2021 | B8: -0.72 | C8: -0.74 | D8: -0.73 | E8: -0.71 | F8: 历史极度宽松：无限量 QE 和零利率，金融系统“水满为患”。 | J8: 2021-第一季度 (Q1) | K8: -0.72
A9: 2022 | B9: -0.62 | C9: -0.45 | D9: -0.38 | E9: -0.28 | F9: 紧缩震荡：加息周期开启，波动率（VIX）上升，信贷利差走阔。 | J9: 2021-第二季度 (Q2) | K9: -0.74
A10: 2023 | B10: -0.22 | C10: -0.32 | D10: -0.36 | E10: -0.48 | F10: 先收后放：经历了 3 月银行业风 | J10: Data Source | K10: Uploaded file: 基础数据v2.xlsx
J11: Transform | K11: Zero removed; numeric-like text parsed for analytics
J12: 2022-第一季度 (Q1) | K12: -0.62
J13: 2022-第二季度 (Q2) | K13: -0.45
J14: 2022-第三季度 (Q3) | K14: -0.38
J15: 2022-第四季度 (Q4) | K15: -0.28
J16: 2023-先收后放：经历了 3 月银行业风-第一季度 (Q1) | K16: -0.22
J17: 2023-先收后放：经历了 3 月银行业风-第二季度 (Q2) | K17: -0.32
J18: 2023-先收后放：经历了 3 月银行业风-第三季度 (Q3) | K18: -0.36
J19: 2023-先收后放：经历了 3 月银行业风-第四季度 (Q4) | K19: -0.48

Sheet S22_GDP Now 预测
A1: GDP Now 预测
A3: Category | B3: Growth | C3: Primary Metric | D3: 贡献度 (估算) | E3: Frequency | F3: Mixed | H3: Back to Dashboard
A4: Orientation | B4: HigherBetter | C4: Latest | D4: 0.021 | E4: Previous | F4: 0.03
A7: 主要贡献项 | B7: 贡献度 (估算) | C7: 趋势观察 | J7: TimePoint | K7: Series
A8: 个人消费支出 (PCE) | B8: 0.021 | C8: 韧性十足：劳动力市场表现稳健，零售额增长支撑了这一大头。 | J8: 个人消费支出 (PCE) | K8: 0.021
A9: 国内私人总投资 | B9: 0.006 | C9: 资本开支回暖：受益于 AI 基础设施投入及宽松金融条件。 | J9: 国内私人总投资 | K9: 0.006
A10: 政府支出 | B10: 0.004 | C10: 财政扩张：在大选后的政策执行期，政府支出保持在稳健水平。 | J10: Data Source | K10: Uploaded file: 基础数据v2.xlsx
A11: 净出口与库存变动 | B11: -0.001 | C11: 轻微拖累：库存积压有所放缓，出口受美元走强影响略显乏力。 | J11: Transform | K11: Zero removed; numeric-like text parsed for analytics
A16: GDP Now 预测
A17: time | B17: 预测值
A18: 46083 | B18: 0.03
A19: 46087 | B19: 0.021
A20: 46093

Sheet S23_St. Louis Fed Economic News
A1: St. Louis Fed Economic News Ind
A3: Category | B3: Growth | C3: Primary Metric | D3: St. Louis Fed Economic News Ind | E3: Frequency | F3: Quarterly | H3: Back to Dashboard
A4: Orientation | B4: HigherBetter | C4: Latest | D4: 2.41 | E4: Previous | F4: -0.0017
A7: 年份 | B7: 第一季度 (Q1) | C7: 第二季度 (Q2) | D7: 第三季度 (Q3) | E7: 第四季度 (Q4) | F7: 宏观环境解读 | J7: TimePoint | K7: Series
A8: 2021 | B8: 0.1018 | C8: 0.0903 | D8: 0.0685 | E8: 0.0375 | F8: 超常规增长：疫苗普及后的报复性消费与复工推动。 | J8: 2021-第一季度 (Q1) | K8: 0.1018
A9: 2022 | B9: 0.0196 | C9: 0.041 | D9: 0.013 | E9: 0.0044 | F9: 增速换挡：虽然通胀飙升，但 Q2 出现了一次意外的经济脉冲。 | J9: 2021-第二季度 (Q2) | K9: 0.0903
A10: 2023 | B10: 0.0056 | C10: 0.008 | D10: 0.0231 | E10: 0.0203 | F10: 软着陆过渡：受银行业危机扰动 Q1 偏弱，随后逐步回升。 | J10: Data Source | K10: Uploaded file: 基础数据v2.xlsx
A11: 2024 | B11: 0.0171 | C11: 0.0114 | D11: 0.0177 | E11: 0.0238 | F11: 稳健韧性：在限制性利率下，经济新闻持续释放温和增长信号。 | J11: Transform | K11: Zero removed; numeric-like text parsed for analytics
A12: 2025 | B12: 0.0307 | C12: 0.0173 | D12: 0.0042 | E12: -0.0017 | F12: 波动起伏：2025 年下半年增长数据显著放缓，反映紧缩滞后效应。 | J12: 2022-第一季度 (Q1) | K12: 0.0196
A13: 2026 | B13: 2.41% (最新) | C13: - | D13: - | E13: - | F13: 当前：截至 3 月初，指数从 Q4 的低谷显著反弹。 | J13: 2022-第二季度 (Q2) | K13: 0.041
J14: 2022-第三季度 (Q3) | K14: 0.013
J15: 2022-第四季度 (Q4) | K15: 0.0044
J16: 2023-第一季度 (Q1) | K16: 0.0056
J17: 2023-第二季度 (Q2) | K17: 0.008
